Workbook

Sheet Fast Representações
B1: Nº do Sistema | C1: Cliente | D1: NF | E1: Faturamento | F1: Produto | G1: Valor Unitário | H1: Quantidade | I1: Valor Total | J1: % Comissão | K1: Comissão Bruta | L1: Imposto | M1: Comissão total | N1: Mês a Receber
B2: 6094 | C2: Alda Veronica | D2: 172882 | E2: 45629 | F2: Renda 18cm | G2: 53.8 | H2: 144.96 | I2: =G2*H2 -> 7798.848 | J2: 0.02 | K2: =I2*J2 -> 155.97696 | L2: =K2*6% -> 9.3586176 | M2: =K2-L2 -> 146.61834 | N2: Fevereiro
B3: 6113 | C3: WWA | D3: 15408 | E3: 45988 | F3: Cotton | G3: 35.66 | H3: 619.729 | I3: =G3*H3 -> 22099.536 | J3: 0.015 | K3: =I3*J3 -> 331.49304 | L3: =K3*6% -> 19.889583 | M3: =K3-L3 -> 311.60346 | N3: Janeiro
B4: 6224 | C4: Doroth de Friburgo | D4: 16375 | E4: 45675 | F4: Liganete Lisa | G4: 30.4 | H4: 132.2 | I4: =G4*H4 -> 4018.88 | J4: 0.02 | K4: =I4*J4 -> 80.3776 | L4: =K4*6% -> 4.822656 | M4: =K4-L4 -> 75.554944 | N4: Fevereiro
B5: 6224 | C5: Doroth de Friburgo | D5: 16375 | E5: 45675 | F5: Liganete Estampada | G5: 25.4 | H5: 183.5 | I5: =G5*H5 -> 4660.9 | J5: 0.02 | K5: =I5*J5 -> 93.218 | L5: =K5*6% -> 5.59308 | M5: =K5-L5 -> 87.62492 | N5: Fevereiro
B6: 6234 | C6: Big Mar | D6: 106645 | E6: 45672 | F6: Cotton | G6: 35.5 | H6: 628.501 | I6: =G6*H6 -> 22311.786 | J6: 0.015 | K6: =I6*J6 -> 334.67678 | L6: =K6*6% -> 20.080607 | M6: =K6-L6 -> 314.59618 | N6: Abril
B7: 6250 | C7: Gilsandro | D7: 161285 | E7: 45673 | F7: Helanca | G7: 25.07 | H7: 1060 | I7: =G7*H7 -> 26574.2 | J7: 0.02 | K7: =I7*J7 -> 531.484 | L7: =K7*6% -> 31.88904 | M7: =K7-L7 -> 499.59496 | N7: Fevereiro
B8: 6302 | C8: Belle Fascino | D8: 161514 | E8: 45679 | F8: Renda 18cm | G8: 53.02 | H8: 90 | I8: =G8*H8 -> 4771.8 | J8: 0.02 | K8: =I8*J8 -> 95.436 | L8: =K8*6% -> 5.72616 | M8: =K8-L8 -> 89.70984 | N8: Fevereiro
B9: 6376 | C9: Mônica de Almeida | D9: 162191 | E9: 45694 | F9: Renda 18cm | G9: 52.98 | H9: 94.8 | I9: =G9*H9 -> 5022.504 | J9: 0.02 | K9: =I9*J9 -> 100.45008 | L9: =K9*6% -> 6.0270048 | M9: =K9-L9 -> 94.423075 | N9: Março
B10: 6485 | C10: Ayla | D10: 107708 | E10: 45699 | F10: Cotton | G10: 37.55 | H10: 331.537 | I10: =G10*H10 -> 12449.214 | J10: 0.015 | K10: =I10*J10 -> 186.73822 | L10: =K10*6% -> 11.204293 | M10: =K10-L10 -> 175.53392 | N10: Abril
B11: 6517 | C11: Donna Emilinha | D11: 108374 | E11: 45713 | F11: PP | G11: 29.47 | H11: 433.705 | I11: =G11*H11 -> 12781.286 | J11: 0.015 | K11: =I11*J11 -> 191.7193 | L11: =K11*6% -> 11.503158 | M11: =K11-L11 -> 180.21614 | N11: Maio
B12: 6549 | C12: Belle Fascino | D12: 163418 | E12: 45734 | F12: Renda 18cm | G12: 53.02 | H12: 215.8 | I12: =G12*H12 -> 11441.716 | J12: 0.02 | K12: =I12*J12 -> 228.83432 | L12: =K12*6% -> 13.730059 | M12: =K12-L12 -> 215.10426 | N12: Abril
B13: 6604 | C13: Big Mar | D13: 108524 | E13: 45721 | F13: Cotton | G13: 37.43 | H13: 1120.031 | I13: =G13*H13 -> 41922.76 | J13: 0.015 | K13: =I13*J13 -> 628.84141 | L13: =K13*6% -> 37.730484 | M13: =K13-L13 -> 591.11092 | N13: Maio
... B18: 6960 | C18: Big Mar | D18: 110809 | E18: 45785 | F18: Cotton | G18: 40 | H18: 978.461 | I18: =G18*H18 -> 39138.44 | J18: 0.015 | K18: =I18*J18 -> 587.0766 | L18: =K18*6% -> 35.224596 | M18: =K18-L18 -> 551.852 | N18: Julho
B19: MAMUT | C19: Venda descontada | D19: 151515 | E19: 51 | F19: BOXER | G19: 4500 | H19: 6.7 | I19: =G19*H19 -> 30150 | J19: 0.015 | K19: =I19*J19 -> 452.25 | L19: =K19*6% -> 27.135 | M19: =K19-L19 -> 425.115 | N19: Maio
B20: 7027 | C20: Reviro | D20: 165149 | E20: 45779 | F20: Suede Estampado | G20: 28.62 | H20: 176.6 | I20: =G20*H20 -> 5054.292 | J20: 0.02 | K20: =I20*J20 -> 101.08584 | L20: =K20*6% -> 6.0651504 | M20: =K20-L20 -> 95.02069 | N20: Junho
B21: 7116 | C21: Irresistivel | D21: 111374 | E21: 45799 | F21: Cotton | G21: 39.79 | H21: 331.977 | I21: =G21*H21 -> 13209.365 | J21: 0.015 | K21: =I21*J21 -> 198.14047 | L21: =K21*6% -> 11.888428 | M21: =K21-L21 -> 186.25204 | N21: Julho
B22: 7123 | C22: Am da Silva | D22: 165854 | E22: 45800 | F22: Suede Estampado | G22: 27.78 | H22: 23.4 | I22: =G22*H22 -> 650.052 | J22: 0.02 | K22: =I22*J22 -> 13.00104 | L22: =K22*6% -> 0.7800624 | M22: =K22-L22 -> 12.220978 | N22: Junho
B23: 7125 | C23: Belle Fascino | D23: 111362 | E23: 45799 | F23: Cotton | G23: 39.28 | H23: 214.3 | I23: =G23*H23 -> 8417.704 | J23: 0.015 | K23: =I23*J23 -> 126.26556 | L23: =K23*6% -> 7.5759336 | M23: =K23-L23 -> 118.68963 | N23: Julho
B24: 7213 | C24: Reviro | D24: 166410 | E24: 45817 | F24: Suede Estampado | G24: 28.62 | H24: 122.25 | I24: =G24*H24 -> 3498.795 | J24: 0.02 | K24: =I24*J24 -> 69.9759 | L24: =K24*6% -> 4.198554 | M24: =K24-L24 -> 65.777346 | N24: Julho
B25: 7262 | C25: Be Bless | D25: 166733 | E25: 45825 | F25: Suede Estampado | G25: 28.62 | H25: 119.6 | I25: =G25*H25 -> 3422.952 | J25: 0.02 | K25: =I25*J25 -> 68.45904 | L25: =K25*6% -> 4.1075424 | M25: =K25-L25 -> 64.351498 | N25: Julho
B26: 7290 | C26: Big Mar | D26: 112786 | E26: 45839 | F26: Cotton | G26: 40 | H26: 566.277 | I26: =G26*H26 -> 22651.08 | J26: 0.015 | K26: =I26*J26 -> 339.7662 | L26: =K26*6% -> 20.385972 | M26: =K26-L26 -> 319.38023 | N26: Outubro
B27: 7291 | C27: Irresistivel | D27: 112833 | E27: 45839 | F27: Cotton | G27: 38.95 | H27: 286.545 | I27: =G27*H27 -> 11160.928 | J27: 0.015 | K27: =I27*J27 -> 167.41392 | L27: =K27*6% -> 10.044835 | M27: =K27-L27 -> 157.36908 | N27: Outubro
B28: 7349 | C28: Irresistivel | D28: 113202 | E28: 45849 | F28: Cotton | G28: 40.18 | H28: 196.181 | I28: =G28*H28 -> 7882.5526 | J28: 0.015 | K28: =I28*J28 -> 118.23829 | L28: =K28*6% -> 7.0942973 | M28: =K28-L28 -> 111.14399 | N28: Outubro
B29: 7398 | C29: WWA | D29: 113721 | E29: 45862 | F29: Cotton | G29: 38.66 | H29: 739.463 | I29: =G29*H29 -> 28587.64 | J29: 0.015 | K29: =I29*J29 -> 428.81459 | L29: =K29*6% -> 25.728876 | M29: =K29-L29 -> 403.08572 | N29: Outubro
B30: 7427 | C30: Be Bless | D30: 168034 | E30: 45867 | F30: Suede Estampado | G30: 28.62 | H30: 125.1 | I30: =G30*H30 -> 3580.362 | J30: 0.02 | K30: =I30*J30 -> 71.60724 | L30: =K30*6% -> 4.2964344 | M30: =K30-L30 -> 67.310806 | N30: Agosto
B31: 7598 | C31: Big Mar | D31: 114418 | E31: 45882 | F31: Cotton | G31: 40 | H31: 1012.284 | I31: =G31*H31 -> 40491.36 | J31: 0.015 | K31: =I31*J31 -> 607.3704 | L31: =K31*6% -> 36.442224 | M31: =K31-L31 -> 570.92818 | N31: Dezembro
... B39: 7959 | C39: Be Bless | D39: 170956 | E39: 45961 | F39: Suede Estampado | G39: 28.12 | H39: 97.1 | I39: =G39*H39 -> 2730.452 | J39: 0.02 | K39: =I39*J39 -> 54.60904 | L39: =K39*6% -> 3.2765424 | M39: =K39-L39 -> 51.332498 | N39: Novembro
B40: 8029 | C40: Entrelinhas | F40: Renda 18cm | G40: 0 | I40: =G40*H40 -> 0 | K40: =I40*J40 -> 0 | L40: =K40*6% -> 0 | M40: =K40-L40 -> 0
B41: 8047 | C41: Belle Fascinio | D41: 118756 | E41: 45992 | F41: Malha Forro | G41: 35.41 | H41: 134.258 | I41: =G41*H41 -> 4754.0758 | J41: 0.015 | K41: =I41*J41 -> 71.311137 | L41: =K41*6% -> 4.2786682 | M41: =K41-L41 -> 67.032468
B42: 8100 | C42: Be Bless | D42: 171693 | E42: 45993 | F42: Suede Estampado | G42: 28.12 | H42: 100.4 | I42: =G42*H42 -> 2823.248 | J42: 0.02 | K42: =I42*J42 -> 56.46496 | L42: =K42*6% -> 3.3878976 | M42: =K42-L42 -> 53.077062
G43: 0 | I43: =G43*H43 -> 0 | K43: =I43*J43 -> 0 | L43: =K43*6% -> 0 | M43: =K43-L43 -> 0
G44: 0 | I44: =G44*H44 -> 0 | K44: =I44*J44 -> 0 | L44: =K44*6% -> 0 | M44: =K44-L44 -> 0
G45: 0 | I45: =G45*H45 -> 0 | K45: =I45*J45 -> 0 | L45: =K45*6% -> 0 | M45: =K45-L45 -> 0
G46: 0 | I46: =G46*H46 -> 0 | K46: =I46*J46 -> 0 | L46: =K46*6% -> 0 | M46: =K46-L46 -> 0
G47: 0 | I47: =G47*H47 -> 0 | K47: =I47*J47 -> 0 | L47: =K47*6% -> 0 | M47: =K47-L47 -> 0
G48: 0 | I48: =G48*H48 -> 0 | K48: =I48*J48 -> 0 | L48: =K48*6% -> 0 | M48: =K48-L48 -> 0
G49: 0 | I49: =G49*H49 -> 0 | K49: =I49*J49 -> 0 | L49: =K49*6% -> 0 | M49: =K49-L49 -> 0
G50: 0 | I50: =G50*H50 -> 0 | K50: =I50*J50 -> 0 | L50: =K50*6% -> 0 | M50: =K50-L50 -> 0
G51: 0 | I51: =G51*H51 -> 0 | K51: =I51*J51 -> 0 | L51: =K51*6% -> 0 | M51: =K51-L51 -> 0
...

Sheet Fast Malhas
B1: Nº Processo | C1: Cliente | D1: Custo | E1: Quantidade | F1: Valor Total | G1: % Comissão | H1: Comissão | I1: Mês a Receber
B2: 1389 | C2: Entrelinhas | D2: 27.15 | E2: 24380 | F2: =D2*E2 -> 661917 | G2: 0.01 | H2: =F2*G2 -> 6619.17 | I2: Janeiro
B3: 1508 | C3: Entrelinhas | D3: 48.11 | E3: 10041.4 | F3: =D3*E3 -> 483091.75 | G3: 0.01 | H3: =F3*G3 -> 4830.9175 | I3: Abril
B4: 1558 | C4: AV Moda | D4: 27.1 | E4: 6915.93 | F4: =D4*E4 -> 187421.7 | G4: 0.01 | H4: =F4*G4 -> 1874.217 | I4: Abril
B5: 1606 | C5: Gabriel Rodrigues | D5: 26.76 | E5: 1300 | F5: =D5*E5 -> 34788 | G5: 0.01 | H5: =F5*G5 -> 347.88 | I5: Janeiro
B6: 1610 | C6: BR Acessórios | D6: 27.07 | E6: 5169.92 | F6: =D6*E6 -> 139949.73 | G6: 0.01 | H6: =F6*G6 -> 1399.4973 | I6: Março
B7: 1611 | C7: GT Moda Intima | D7: 27.07 | E7: 5151.8 | F7: =D7*E7 -> 139459.23 | G7: 0.01 | H7: =F7*G7 -> 1394.5923 | I7: Março
B8: 1612 | C8: Gabriel Rodrigues | D8: 26.8 | E8: 859.17 | F8: =D8*E8 -> 23025.756 | G8: 0.01 | H8: =F8*G8 -> 230.25756 | I8: Fevereiro
B9: 1613 | C9: Kelly Cristina | D9: 27.11 | E9: 3600 | F9: =D9*E9 -> 97596 | G9: 0.01 | H9: =F9*G9 -> 975.96 | I9: Janeiro
B10: 1617 | C10: Entrelinhas | D10: 26.41 | E10: 5006.29 | F10: =D10*E10 -> 132216.12 | G10: 0.01 | H10: =F10*G10 -> 1322.1612 | I10: Fevereiro
B11: 1625 | C11: Fernanda Emanuele | D11: 30 | E11: 1168.26 | F11: =D11*E11 -> 35047.8 | G11: 0.01 | H11: =F11*G11 -> 350.478 | I11: Março
B12: 1626 | C12: Entrelinhas | D12: 51.05 | E12: 5939.62 | F12: =D12*E12 -> 303217.6 | G12: 0.01 | H12: =F12*G12 -> 3032.176 | I12: Abril
B13: 1636 | C13: Entrelinhas | D13: 26.66 | E13: 5188.27 | F13: =D13*E13 -> 138319.28 | G13: 0.01 | H13: =F13*G13 -> 1383.1928 | I13: Março
... B35: 1821 | C35: Entrelinhas | D35: 45.79 | E35: 2903.13 | F35: =D35*E35 -> 132934.32 | G35: 0.01 | H35: =F35*G35 -> 1329.3432 | I35: Novembro
B36: 1822 | C36: Entrelinhas | D36: 46 | E36: 3000 | F36: =D36*E36 -> 138000 | G36: 0.01 | H36: =F36*G36 -> 1380
B37: 1823 | C37: Entrelinhas | D37: 46.19 | E37: 1969.18 | F37: =D37*E37 -> 90956.424 | G37: 0.01 | H37: =F37*G37 -> 909.56424 | I37: Novembro
B38: 1824 | C38: Entrelinhas | D38: 45.71 | E38: 1942.72 | F38: =D38*E38 -> 88801.731 | G38: 0.01 | H38: =F38*G38 -> 888.01731 | I38: Outubro
B39: 1825 | C39: Entrelinhas | D39: 45.61 | E39: 1986.48 | F39: =D39*E39 -> 90603.353 | G39: 0.01 | H39: =F39*G39 -> 906.03353 | I39: Dezembro
B40: 1830 | C40: Joia Intima | D40: 24.78 | E40: 995.99 | F40: =D40*E40 -> 24680.632 | G40: 0.01 | H40: =F40*G40 -> 246.80632 | I40: Maio
B41: 1831 | C41: Kelly Cristina | D41: 26.32 | E41: 4777.24 | F41: =D41*E41 -> 125736.96 | G41: 0.01 | H41: =F41*G41 -> 1257.3696 | I41: Julho
B42: 1832 | C42: BR Acessórios | D42: 26.32 | E42: 720 | F42: =D42*E42 -> 18950.4 | G42: 0.01 | H42: =F42*G42 -> 189.504 | I42: Junho
B43: 1833 | C43: Joia Intima | D43: 25.62 | E43: 4000 | F43: =D43*E43 -> 102480 | G43: 0.01 | H43: =F43*G43 -> 1024.8 | I43: Junho
B44: 1862 | C44: V. da Silva | D44: 46.31 | E44: 1087.58 | F44: =D44*E44 -> 50365.83 | G44: 0.01 | H44: =F44*G44 -> 503.6583 | I44: Setembro
B45: 1864 | C45: Transeg | D45: 48.78 | E45: 3850 | F45: =D45*E45 -> 187803 | G45: 0.01 | H45: =F45*G45 -> 1878.03 | I45: Agosto
B46: 1873 | C46: Entrelinhas | D46: 47.89 | E46: 3035.06 | F46: =D46*E46 -> 145349.02 | G46: 0.01 | H46: =F46*G46 -> 1453.4902 | I46: Agosto
B47: 1883 | C47: Entrelinhas | D47: 22.79 | E47: 536.38 | F47: =D47*E47 -> 12224.1 | G47: 0.01 | H47: =F47*G47 -> 122.241 | I47: Junho
B48: 1884 | C48: Entrelinhas | D48: 26.32 | E48: 2160 | F48: =D48*E48 -> 56851.2 | G48: 0.01 | H48: =F48*G48 -> 568.512 | I48: Julho
... B64: 1966 | C64: Entrelinhas | D64: 27.48 | E64: 1699.4 | F64: =D64*E64 -> 46699.512 | G64: 0.01 | H64: =F64*G64 -> 466.99512 | I64: Novembro
B65: 1995 | C65: Kelly Cristina | D65: 27.89 | E65: 5280 | F65: =D65*E65 -> 147259.2 | G65: 0.01 | H65: =F65*G65 -> 1472.592
B66: 2004 | C66: Entrelinhas | D66: 47.99 | E66: 2881.09 | F66: =D66*E66 -> 138263.51 | G66: 0.01 | H66: =F66*G66 -> 1382.6351 | I66: Setembro
B67: 2018 | C67: Jóia | D67: 27 | E67: 4000 | F67: =D67*E67 -> 108000 | G67: 0.01 | H67: =F67*G67 -> 1080
B68: 2019 | C68: Jóia | D68: 27.04 | E68: 2926.22 | F68: =D68*E68 -> 79124.989 | G68: 0.01 | H68: =F68*G68 -> 791.24989 | I68: Dezembro
B69: 2052 | C69: BR Acessórios | D69: 26.46 | E69: 952.66 | F69: =D69*E69 -> 25207.384 | G69: 0.01 | H69: =F69*G69 -> 252.07384 | I69: Outubro
B70: 2064 | C70: BR Acessórios | D70: 26.92 | E70: 944.21 | F70: =D70*E70 -> 25418.133 | G70: 0.01 | H70: =F70*G70 -> 254.18133 | I70: Novembro
B71: 2070 | C71: Kelly Cristina | D71: 27.05 | E71: 5280 | F71: =D71*E71 -> 142824 | G71: 0.01 | H71: =F71*G71 -> 1428.24
B72: 2089 | C72: Kelly Cristina | D72: 27 | E72: 2100 | F72: =D72*E72 -> 56700 | G72: 0.01 | H72: =F72*G72 -> 567
B73: 2130 | C73: Jóia | D73: 24.24 | E73: 2002.62 | F73: =D73*E73 -> 48543.509 | G73: 0.01 | H73: =F73*G73 -> 485.43509 | I73: Dezembro
B74: 2131 | C74: Jóia | D74: 25 | E74: 3000 | F74: =D74*E74 -> 75000 | G74: 0.01 | H74: =F74*G74 -> 750
B75: 2133 | C75: Kelly Cristina | D75: 25.94 | E75: 6523.62 | F75: =D75*E75 -> 169222.7 | G75: 0.01 | H75: =F75*G75 -> 1692.227 | I75: Dezembro
B76: 2135 | C76: Br acessórios | D76: 25.81 | E76: 4417 | F76: =D76*E76 -> 114002.77 | G76: 0.01 | H76: =F76*G76 -> 1140.0277 | I76: Dezembro
...

Sheet Fast Elásticos
A1: Nº Pedido | B1: Cliente | C1: Nota Fiscal | D1: Faturamento | E1: Data de Pagamento | F1: Valor Unitário | G1: Quantidade | H1: Valor Total | I1: % Comissão | J1: Comissão | K1: Mês a Receber
A2: 6144 | B2: Entrelinhas | F2: 12.1 | G2: 120 | H2: =F2*G2 -> 1452 | I2: 0.02 | J2: =H2*I2 -> 29.04 | K2: Março
A3: 6303 | B3: Miranda e Fraga | E3: 45678 | F3: 12.6 | G3: 168 | H3: =F3*G3 -> 2116.8 | I3: 0.02 | J3: =H3*I3 -> 42.336 | K3: Fevereiro
A4: 6420 | B4: Use Crisan | E4: 45688 | F4: 11.7 | G4: 396 | H4: =F4*G4 -> 4633.2 | I4: 0.02 | J4: =H4*I4 -> 92.664 | K4: Fevereiro
A5: 6587 | B5: F7 New Style | E5: 45707 | F5: 11.7 | G5: 240 | H5: =F5*G5 -> 2808 | I5: 0.02 | J5: =H5*I5 -> 56.16 | K5: Março
A6: 6663 | B6: Siqueira | C6: 29121 | D6: 45735 | F6: 11.7 | G6: 1248 | H6: =F6*G6 -> 14601.6 | I6: 0.02 | J6: =H6*I6 -> 292.032 | K6: Abril
A7: 6716 | B7: Miranda e Fraga | E7: 45735 | F7: 11.7 | G7: 204 | H7: =F7*G7 -> 2386.8 | I7: 0.02 | J7: =H7*I7 -> 47.736 | K7: Abril
A8: 7028 | B8: Miranda e Fraga | E8: 45785 | F8: 11.7 | G8: 216 | H8: =F8*G8 -> 2527.2 | I8: 0.02 | J8: =H8*I8 -> 50.544 | K8: Junho
A9: 7041 | B9: Siqueira | F9: 11.7 | G9: 360 | H9: =F9*G9 -> 4212 | I9: 0.02 | J9: =H9*I9 -> 84.24 | K9: Junho
A10: 7229 | B10: Miranda e fraga | C10: 29541 | D10: 45787 | E10: 45824 | F10: 11.7 | G10: 240 | H10: =F10*G10 -> 2808 | I10: 0.02 | J10: =H10*I10 -> 56.16 | K10: Julho
A11: 7279 | B11: Siqueira | F11: 11.7 | G11: 1404 | H11: =F11*G11 -> 16426.8 | I11: 0.02 | J11: =H11*I11 -> 328.536 | K11: Julho
A12: 7372 | B12: Siqueira | F12: 11.7 | G12: 396 | H12: =F12*G12 -> 4633.2 | I12: 0.02 | J12: =H12*I12 -> 92.664 | K12: Agosto
A13: 7430 | B13: Siqueira | F13: 11.7 | G13: 240 | H13: =F13*G13 -> 2808 | I13: 0.02 | J13: =H13*I13 -> 56.16 | K13: Agosto
A14: 7434 | B14: Miranda e fraga | F14: 11.7 | G14: 240 | H14: =F14*G14 -> 2808 | I14: 0.02 | J14: =H14*I14 -> 56.16 | K14: Agosto
A15: 7607 | B15: Mauricio Valberto | C15: 30042 | F15: 11.7 | G15: 240 | H15: =F15*G15 -> 2808 | I15: 0.02 | J15: =H15*I15 -> 56.16 | K15: Setembro
A16: 7681 | B16: Gabriel Rodrigues | C16: 30156 | D16: 45926 | E16: 45925 | F16: 11.7 | G16: 216 | H16: =F16*G16 -> 2527.2 | I16: 0.02 | J16: =H16*I16 -> 50.544 | K16: Novembro
A17: 7727 | B17: D.A.C.B Grativol | C17: 30237 | D17: 45938 | E17: 45938 | F17: 11.7 | G17: 120 | H17: =F17*G17 -> 1404 | I17: 0.02 | J17: =H17*I17 -> 28.08 | K17: Novembro
A18: 7737 | B18: F7 New Style | C18: 30236 | D18: 45938 | E18: 45938 | F18: 11.7 | G18: 336 | H18: =F18*G18 -> 3931.2 | I18: 0.02 | J18: =H18*I18 -> 78.624 | K18: Novembro
A19: 7753 | B19: Miranda e fraga | C19: 30238 | D19: 45938 | E19: 45939 | F19: 11.7 | G19: =16*12 -> 192 | H19: =F19*G19 -> 2246.4 | I19: 0.02 | J19: =H19*I19 -> 44.928 | K19: Novembro
A20: 7777 | B20: Siqueira | C20: 30419 | D20: 45965 | E20: 07/11/2025 / 14/11/2025 | F20: 11.7 | G20: 1980 | H20: =F20*G20 -> 23166 | I20: 0.02 | J20: =H20*I20 -> 463.32 | K20: Dezembro
A21: 7778 | B21: Mauricio Valberto | C21: 30344 | D21: 45953 | E21: 30/10/2025 / 07/11/2025 | F21: 11.7 | G21: 132 | H21: =F21*G21 -> 1544.4 | I21: 0.02 | J21: =H21*I21 -> 30.888 | K21: Novembro
A22: 7804 | B22: D'Bellus | C22: 30345 | D22: 45953 | E22: 28/10/2025 / 07/11/2025 | F22: 11.7 | G22: 132 | H22: =F22*G22 -> 1544.4 | I22: 0.02 | J22: =H22*I22 -> 30.888 | K22: Novembro
A23: 7937 | B23: Miranda e fraga | C23: 30381 | D23: 45959 | E23: 45959 | F23: 11.7 | G23: 48 | H23: =F23*G23 -> 561.6 | I23: 0.02 | J23: =H23*I23 -> 11.232 | K23: Novembro
A24: 8023 | B24: Mauricio Valberto | E24: 46006 | F24: 11.7 | G24: 228 | H24: =F24*G24 -> 2667.6 | I24: 0.02 | J24: =H24*I24 -> 53.352 | K24: Dezembro
A25: 8073 | B25: Gabriel Rodrigues | C25: 30633 | D25: 46001 | F25: 11.7 | G25: 228 | H25: =F25*G25 -> 2667.6 | I25: 0.02 | J25: =H25*I25 -> 53.352 | K25: Dezembro
A26: 8117 | B26: F7 New Style | E26: 46001 | F26: 11.7 | G26: 180 | H26: =F26*G26 -> 2106 | I26: 0.02 | J26: =H26*I26 -> 42.12 | K26: Dezembro
F27: 11.7 | G27: 0 | H27: =F27*G27 -> 0 | I27: 0.02 | J27: =H27*I27 -> 0
F28: 11.7 | G28: 0 | H28: =F28*G28 -> 0 | I28: 0.02 | J28: =H28*I28 -> 0
F29: 11.7 | G29: 0 | H29: =F29*G29 -> 0 | I29: 0.02 | J29: =H29*I29 -> 0
F30: 11.7 | G30: 0 | H30: =F30*G30 -> 0 | I30: 0.02 | J30: =H30*I30 -> 0
F31: 11.7 | G31: 0 | H31: =F31*G31 -> 0 | I31: 0.02 | J31: =H31*I31 -> 0
F32: 11.7 | G32: 0 | H32: =F32*G32 -> 0 | I32: 0.02 | J32: =H32*I32 -> 0
F33: 11.7 | G33: 0 | H33: =F33*G33 -> 0 | I33: 0.02 | J33: =H33*I33 -> 0
F34: 11.7 | G34: 0 | H34: =F34*G34 -> 0 | I34: 0.02 | J34: =H34*I34 -> 0
F35: 11.7 | G35: 0 | H35: =F35*G35 -> 0 | I35: 0.02 | J35: =H35*I35 -> 0
F36: 11.7 | G36: 0 | H36: =F36*G36 -> 0 | I36: 0.02 | J36: =H36*I36 -> 0
F37: 11.7 | G37: 0 | H37: =F37*G37 -> 0 | I37: 0.02 | J37: =H37*I37 -> 0
F38: 11.7 | G38: 0 | H38: =F38*G38 -> 0 | I38: 0.02 | J38: =H38*I38 -> 0
... F65: 11.7 | G65: 0 | H65: =F65*G65 -> 0 | I65: 0.02 | J65: =H65*I65 -> 0
A66: 8073 | B66: Gabriel Rodrigues

Sheet Island
B1: Data de entrada | C1: Nº do Pedido | D1: Cliente | E1: Produto | F1: Preço | G1: Quantidade | H1: Valor Total | I1: Status | J1: % Comissão | K1: Comissão total | L1: Mês a Receber
B2: 45636 | C2: 1437 | D2: Gilbrto Gastin | E2: Poliamida | F2: 54.9 | G2: 73.66 | H2: =F2*G2 -> 4043.934 | I2: Pago | J2: 0.02 | K2: =H2*J2 -> 80.87868 | L2: Janeiro
B3: 45638 | C3: 1440 | D3: Gabriel Rodrigues | E3: Poliamida | F3: 54.9 | G3: 159.94 | H3: =F3*G3 -> 8780.706 | I3: Pago | J3: 0.02 | K3: =H3*J3 -> 175.61412 | L3: Janeiro
B4: 45639 | C4: 1442 | D4: Mirandae Fraga | E4: Viés | F4: 14.9 | G4: 36 | H4: =F4*G4 -> 536.4 | I4: Pago | J4: 0.02 | K4: =H4*J4 -> 10.728 | L4: Janeiro
B5: 45664 | C5: 1449 | D5: MS Fabulosa | E5: Romantic | F5: 29.9 | G5: 193.3 | H5: =F5*G5 -> 5779.67 | I5: Pago | J5: 0.02 | K5: =H5*J5 -> 115.5934 | L5: Fevereiro
B6: 45665 | C6: 1453 | D6: Tbow | E6: Romantic | F6: 29.9 | G6: 194 | H6: =F6*G6 -> 5800.6 | I6: Pago | J6: 0.02 | K6: =H6*J6 -> 116.012 | L6: Fevereiro
B7: 45665 | C7: 1455 | D7: Gabriel Mafort | E7: Poliamida | F7: 54.9 | G7: 160.97 | H7: =F7*G7 -> 8837.253 | I7: Pago | J7: 0.02 | K7: =H7*J7 -> 176.74506 | L7: Fevereiro
B8: 45665 | C8: 1456 | D8: Tbow | E8: Suplex Zero | F8: 26 | G8: 95.53 | H8: =F8*G8 -> 2483.78 | I8: Pago | J8: 0.02 | K8: =H8*J8 -> 49.6756 | L8: Fevereiro
B9: 45666 | C9: 1468 | D9: MS Fabulosa | E9: Romantic | F9: 29.9 | G9: 97 | H9: =F9*G9 -> 2900.3 | I9: Pago | J9: 0.02 | K9: =H9*J9 -> 58.006 | L9: Fevereiro
B10: 45673 | C10: 1469 | D10: Gilberto gastin | E10: Poliamida | F10: 54.9 | G10: 14.47 | H10: =F10*G10 -> 794.403 | I10: Pago | J10: 0.02 | K10: =H10*J10 -> 15.88806 | L10: Fevereiro
B11: 45692 | C11: 1494 | D11: Gabriel Rodrigues | E11: Poliamida | F11: 56.9 | G11: 44.9 | H11: =F11*G11 -> 2554.81 | I11: Pago | J11: 0.02 | K11: =H11*J11 -> 51.0962 | L11: Março
B12: 45692 | C12: 1495 | D12: F7 new Style | E12: Romantic | F12: 29.9 | G12: 38.45 | H12: =F12*G12 -> 1149.655 | I12: Pago | J12: 0.02 | K12: =H12*J12 -> 22.9931 | L12: Março
B13: 45692 | C13: 1496 | D13: Tbow | E13: Romantic | F13: 29.9 | G13: 77.56 | H13: =F13*G13 -> 2319.044 | I13: Pago | J13: 0.02 | K13: =H13*J13 -> 46.38088 | L13: Março
... B35: 45856 | C35: 1781 | D35: Gabriel Rodrigues | E35: Romantic | F35: 26.9 | G35: 53.05 | H35: =F35*G35 -> 1427.045 | I35: Pago | J35: 0.02 | K35: =H35*J35 -> 28.5409 | L35: Agosto
H36: =F36*G36 -> 0 | K36: =H36*J36 -> 0
B37: 45967 | C37: 86373 | D37: Dieu Fort | E37: Tanga Maju | F37: 2.8 | G37: 3165 | H37: =F37*G37 -> 8862 | I37: Pago | J37: 0.02 | K37: =H37*J37 -> 177.24 | L37: Dezembro
B38: 45968 | C38: 86568 | D38: Dieu Fort | E38: Cós Laser | F38: 3.3 | G38: 780 | H38: =F38*G38 -> 2574 | I38: Pago | J38: 0.02 | K38: =H38*J38 -> 51.48 | L38: Dezembro
B39: 45968 | C39: 86568 | D39: Dieu Fort | E39: Tanga Laser | F39: 3.1 | G39: 2005 | H39: =F39*G39 -> 6215.5 | I39: Pago | J39: 0.02 | K39: =H39*J39 -> 124.31 | L39: Dezembro
A40: 2025 | B40: 45974 | C40: 87188 | D40: Dieu Fort | E40: Tanga Maju | F40: 2.8 | G40: 2260 | H40: =F40*G40 -> 6328 | I40: Pago | J40: 0.02 | K40: =H40*J40 -> 126.56 | L40: Dezembro
B41: 45975 | C41: 87242 | D41: Dieu Fort | E41: Tanga Maju | F41: 2.8 | G41: 935 | H41: =F41*G41 -> 2618 | I41: Pago | J41: 0.02 | K41: =H41*J41 -> 52.36 | L41: Dezembro
B42: 45987 | C42: 87751 | D42: Dieu Fort | E42: Tanga Maju | F42: 2.8 | G42: 1870 | H42: =F42*G42 -> 5236 | I42: Pago | J42: 0.02 | K42: =H42*J42 -> 104.72 | L42: Dezembro
H43: =F43*G43 -> 0 | K43: =H43*J43 -> 0
H44: =F44*G44 -> 0 | K44: =H44*J44 -> 0
H45: =F45*G45 -> 0 | K45: =H45*J45 -> 0
H46: =F46*G46 -> 0 | K46: =H46*J46 -> 0
H47: =F47*G47 -> 0 | K47: =H47*J47 -> 0
H48: =F48*G48 -> 0 | K48: =H48*J48 -> 0
H49: =F49*G49 -> 0 | K49: =H49*J49 -> 0
H50: =F50*G50 -> 0 | K50: =H50*J50 -> 0
H51: =F51*G51 -> 0 | K51: =H51*J51 -> 0
H52: =F52*G52 -> 0 | K52: =H52*J52 -> 0
H53: =F53*G53 -> 0 | K53: =H53*J53 -> 0
H54: =F54*G54 -> 0 | K54: =H54*J54 -> 0
... H902: =F902*G902 -> 0 | K902: =H902*J902 -> 0

Sheet MR Têxtil
B1: Data de entrada | C1: Cliente | D1: Produto | E1: Quantidade | F1: Preço | G1: Valor | H1: Status | I1: % Comissão | K1: Comissão Líquida | L1: Mês a receber
B2: 45672 | C2: F7 | D2: Romantic | E2: 192.45 | F2: 28.4 | G2: =E2*F2 -> 5465.58 | H2: Pago | I2: 0.02 | K2: =G2*I2 -> 109.3116 | L2: Fevereiro
B3: 45672 | C3: Leo | D3: Romantic | E3: 18.1 | F3: 28.39 | G3: =E3*F3 -> 513.859 | H3: Pago | I3: 0.02 | K3: =G3*I3 -> 10.27718 | L3: Fevereiro
B4: 45673 | C4: Andreia | D4: Romantic | E4: 74.07 | F4: 28.4 | G4: =E4*F4 -> 2103.588 | H4: Pago | I4: 0.02 | K4: =G4*I4 -> 42.07176 | L4: Fevereiro
B5: 45679 | C5: Gabriel | D5: Romantic | E5: 112.4 | F5: 29.9 | G5: =E5*F5 -> 3360.76 | H5: Pago | I5: 0.02 | K5: =G5*I5 -> 67.2152 | L5: Fevereiro
B6: 45688 | C6: Gabriel | D6: Romantic | E6: 33.6 | F6: 29.9 | G6: =E6*F6 -> 1004.64 | H6: Pago | I6: 0.02 | K6: =G6*I6 -> 20.0928 | L6: Fevereiro
B7: 45671 | C7: Auvo | D7: Romantic | E7: 547.82 | F7: 28.4 | G7: =E7*F7 -> 15558.088 | H7: Pago | I7: 0.01 | K7: =G7*I7 -> 155.58088 | L7: Março
B8: 45691 | C8: F7 | D8: Romantic | E8: 185.4 | F8: 28.4 | G8: =E8*F8 -> 5265.36 | H8: Pago | I8: 0.01 | K8: =G8*I8 -> 52.6536 | L8: Março
B9: 45693 | C9: Andreia | D9: Romantic | E9: 189.9 | F9: 28.4 | G9: =E9*F9 -> 5393.16 | H9: Pago | I9: 0.01 | K9: =G9*I9 -> 53.9316 | L9: Março
B10: 45693 | C10: F7 | D10: Romantic | E10: 59.66 | F10: 28.4 | G10: =E10*F10 -> 1694.344 | H10: Pago | I10: 0.01 | K10: =G10*I10 -> 16.94344 | L10: Março
B11: 45694 | C11: Auvo | D11: Romantic | E11: 313.99 | F11: 28.4 | G11: =E11*F11 -> 8917.316 | H11: Pago | I11: 0.01 | K11: =G11*I11 -> 89.17316 | L11: Abril
B12: 45694 | C12: Gabriel | D12: Romantic | E12: 36.68 | F12: 29.9 | G12: =E12*F12 -> 1096.732 | H12: Pago | I12: 0.02 | K12: =G12*I12 -> 21.93464 | L12: Março
B13: 12/02//2025 | C13: Gabriel | D13: Romantic | E13: 36.62 | F13: 29.9 | G13: =E13*F13 -> 1094.938 | H13: Pago | I13: 0.02 | K13: =G13*I13 -> 21.89876 | L13: Março
B14: 13/02//2025 | C14: Gabriel | D14: Romantic | E14: 37.15 | F14: 29.9 | G14: =E14*F14 -> 1110.785 | H14: Pago | I14: 0.02 | K14: =G14*I14 -> 22.2157 | L14: Março
B15: 45707 | C15: F7 | D15: Romantic | E15: 152.44 | F15: 28.4 | G15: =E15*F15 -> 4329.296 | H15: Pago | I15: 0.01 | K15: =G15*I15 -> 43.29296 | L15: Março
B16: 45707 | C16: Auvo | D16: Romantic | E16: 835.22 | F16: 28.4 | G16: =E16*F16 -> 23720.248 | H16: Pago | I16: 0.01 | K16: =G16*I16 -> 237.20248 | L16: Maio
B17: 45708 | C17: Fabio de Simas | D17: Romantic | E17: 187.7 | F17: 26 | G17: =E17*F17 -> 4880.2 | H17: Pago | I17: 0.01 | K17: =G17*I17 -> 48.802 | L17: Abril
B18: 45709 | C18: Gabriel | D18: Romantic | E18: 56.61 | F18: 29.9 | G18: =E18*F18 -> 1692.639 | H18: Pago | I18: 0.02 | K18: =G18*I18 -> 33.85278 | L18: Março
B19: 45726 | C19: Gabriel | D19: Romantic | E19: 74.87 | F19: 29.9 | G19: =E19*F19 -> 2238.613 | H19: Pago | I19: 0.02 | K19: =G19*I19 -> 44.77226 | L19: Abril
B20: 45727 | C20: Andreia | D20: Romantic | E20: 19.18 | F20: 28.9 | G20: =E20*F20 -> 554.302 | H20: Pago | I20: 0.02 | K20: =G20*I20 -> 11.08604 | L20: Abril
B21: 45729 | C21: Andreia | D21: Romantic | E21: 94.6 | F21: 28.9 | G21: =E21*F21 -> 2733.94 | H21: Pago | I21: 0.02 | K21: =G21*I21 -> 54.6788 | L21: Abril
B22: 45729 | C22: Andreia | D22: Romantic | E22: 19.13 | F22: 28.9 | G22: =E22*F22 -> 552.857 | H22: Pago | I22: 0.02 | K22: =G22*I22 -> 11.05714 | L22: Abril
B23: 45734 | C23: Gabriel | D23: Romantic | E23: 37.81 | F23: 29.9 | G23: =E23*F23 -> 1130.519 | H23: Pago | I23: 0.02 | K23: =G23*I23 -> 22.61038 | L23: Abril
B24: 45736 | C24: Gabriel | D24: Romantic | E24: 37.23 | F24: 29.9 | G24: =E24*F24 -> 1113.177 | H24: Pago | I24: 0.02 | K24: =G24*I24 -> 22.26354 | L24: Abril
B25: 45740 | C25: Gabriel | D25: Romantic | E25: 376.73 | F25: 29.9 | G25: =E25*F25 -> 11264.227 | H25: Pago | I25: 0.02 | K25: =G25*I25 -> 225.28454 | L25: Abril
B26: 45748 | C26: Gabriel | D26: Romantic | E26: 236.45 | F26: 29.9 | G26: =E26*F26 -> 7069.855 | H26: Pago | I26: 0.02 | K26: =G26*I26 -> 141.3971 | L26: Maio
B27: 45761 | C27: Gabriel | D27: Romantic | E27: 260.49 | F27: 29.9 | G27: =E27*F27 -> 7788.651 | H27: Pago | I27: 0.02 | K27: =G27*I27 -> 155.77302 | L27: Maio
B28: 45763 | C28: Andreia | D28: Romantic | E28: 135.51 | F28: 28.9 | G28: =E28*F28 -> 3916.239 | H28: Pago | I28: 0.02 | K28: =G28*I28 -> 78.32478 | L28: Maio | M28: Crédito 83
B29: 45771 | C29: Gabriel | D29: Romantic | E29: 285.31 | F29: 29.9 | G29: =E29*F29 -> 8530.769 | H29: Pago | I29: 0.02 | K29: =G29*I29 -> 170.61538 | L29: Maio
B30: 45806 | C30: Gabriel | D30: Romantic | E30: 191.71 | F30: 29.9 | G30: =E30*F30 -> 5732.129 | H30: Pago | I30: 0.02 | K30: =G30*I30 -> 114.64258 | L30: Maio
B31: 45778 | C31: Andreia | D31: Romantic | E31: 38.9 | F31: 28.9 | G31: =E31*F31 -> 1124.21 | H31: Pago | I31: 0.02 | K31: =G31*I31 -> 22.4842 | L31: Junho | M31: Abatido
B32: 45789 | C32: Gabriel | D32: Romantic | E32: 153.09 | F32: 29.9 | G32: =E32*F32 -> 4577.391 | H32: Pago | I32: 0.02 | K32: =G32*I32 -> 91.54782 | L32: Junho
B33: 45791 | C33: Gabriel | D33: Romantic | E33: 151.39 | F33: 29.9 | G33: =E33*F33 -> 4526.561 | H33: Pago | I33: 0.02 | K33: =G33*I33 -> 90.53122 | L33: Junho
B34: 45799 | C34: Gabriel | D34: Romantic | E34: 189.14 | F34: 29 | G34: =E34*F34 -> 5485.06 | H34: Pago | I34: 0.02 | K34: =G34*I34 -> 109.7012 | L34: Junho
B35: 45810 | C35: Gabriel | D35: Romantic | E35: 289.31 | F35: 29 | G35: =E35*F35 -> 8389.99 | H35: Pago | I35: 0.02 | K35: =G35*I35 -> 167.7998 | L35: Junho
B36: 45818 | C36: Auvo | D36: Boxer | E36: 300 | F36: 41.74 | G36: =E36*F36 -> 12522 | H36: Pago | I36: 0.01 | K36: =G36*I36 -> 125.22 | L36: Junho
C37: Gabriel | D37: Boxer | E37: 300 | F37: 41.74 | G37: =E37*F37 -> 12522 | H37: Pago | I37: 0.01 | K37: =G37*I37 -> 125.22 | L37: Julho
B38: 45852 | C38: Gabriel | D38: Romantic | E38: 117.89 | F38: 29 | G38: =E38*F38 -> 3418.81 | H38: Pago | I38: 0.02 | K38: =G38*I38 -> 68.3762 | L38: Agosto
B39: 45853 | C39: Belle Fascino | D39: Viés Poliamida | E39: 120 | F39: 17.5 | G39: =E39*F39 -> 2100 | H39: Pago | I39: 0.02 | K39: =G39*I39 -> 42 | L39: Agosto
B40: 45853 | C40: Belle Fascino | D40: Viés Poliamida | E40: 40 | F40: 17.5 | G40: =E40*F40 -> 700 | H40: Pago | I40: 0.02 | K40: =G40*I40 -> 14 | L40: Agosto
...

Sheet Total Comissão
A1: Fast Representações | B1: =SUMIF('Fast Representações'!N:N,D2,'Fast Representações'!M:M) -> 2953.3118 | D1: Mês a Receber | H1: LEXUS REPRESENTAÇÕES | K1: Pessoa Física
A2: Fast Malhas | B2: =SUMIF('Fast Malhas'!I:I,D2,'Fast Malhas'!H:H) -> 9646.9914 | D2: Dezembro | H2: Recebivel Líquido | I2: 4650.97 | K2: Pró-labore | L2: 1518
A3: Fast Elásticos | B3: =SUMIF('Fast Elásticos'!K:K,D2,'Fast Elásticos'!J:J) -> 612.144 | H3: Imposto | I3: =O4 -> 830.94703 | K3: Inss | L3: =L2*11% -> 166.98 | O3: Imposto empresa
A4: Island | B4: =SUMIF(Island!L:L,D2,Island!K:K) -> 636.67 | K4: IRRF | L4: =L2*27.5% -> 417.45 | O4: =B5*6% -> 830.94703
A5: Total | B5: =SUM(B1:B4) -> 13849.117
A7: MCL | B7: =SUMIF('MR Têxtil'!L:L,D2,'MR Têxtil'!K:K) -> 0
E8: S.N | F8: INSS | G8: IRRF
A9: Janeiro | B9: 8680.5 | D9: Janeiro | E9: 511.31 | F9: 166.98 | G9: 0 | H9: =SUM(E9:G9) -> 678.29
A10: Fevereiro | B10: 4650.97 | D10: Fevereiro | E10: 279.05 | F10: 166.98 | G10: 0 | H10: =SUM(E10:G10) -> 446.03
A11: Março | B11: 5861.72 | D11: Março | E11: =B11*6% -> 351.7032 | F11: 166.98 | G11: 0 | H11: =SUM(E11:G11) -> 518.6832
A12: Abril | B12: 12443.04 | D12: Abril | E12: =B12*6% -> 746.5824 | F12: 166.98 | G12: 0 | H12: =SUM(E12:G12) -> 913.5624
A13: Maio | B13: 4600 | D13: Maio | E13: =B13*6% -> 276 | F13: 166.98 | G13: 0 | H13: =SUM(E13:G13) -> 442.98
A14: Junho | B14: 7471.08 | D14: Junho | E14: =B14*6% -> 448.2648 | F14: 166.98 | G14: 0 | H14: =SUM(E14:G14) -> 615.2448
A15: Julho | B15: 9335.52 | D15: Julho | E15: =B15*6% -> 560.1312 | F15: 166.98 | G15: 0 | H15: =SUM(E15:G15) -> 727.1112
A16: Agosto | B16: 15733.45 | D16: Agosto | E16: =B16*6% -> 944.007 | F16: 166.98 | G16: 0 | H16: =SUM(E16:G16) -> 1110.987
A17: Setembro | B17: 5165 | D17: Setembro | E17: =B17*6% -> 309.9 | F17: 166.98 | G17: 0 | H17: =SUM(E17:G17) -> 476.88
A18: Outubro | B18: 5212.63 | D18: Outubro | E18: =B18*6% -> 312.7578 | F18: 166.98 | G18: 0 | H18: =SUM(E18:G18) -> 479.7378
A19: Novembro | B19: 7175.19 | D19: Novembro | E19: =B19*6% -> 430.5114 | F19: 166.98 | G19: 0 | H19: =SUM(E19:G19) -> 597.4914
A20: Dezembro | B20: 0 | D20: Dezembro | E20: =B20*6% -> 0 | G20: 0 | H20: =SUM(E20:G20) -> 0

Sheet Apurações
B3: Mês | C3: Comissões | D3: S.N | E3: INSS | F3: IRRF | G3: Impostos totais
B4: Janeiro | C4: 0 | D4: =A4*6% -> 0 | E4: 166.98 | F4: 0 | G4: =SUM(D4:F4) -> 166.98
B5: Fevereiro | C5: 0 | D5: =A5*6% -> 0 | E5: 166.98 | F5: 0 | G5: =SUM(D5:F5) -> 166.98
B6: Março | C6: 0 | D6: =A6*6% -> 0 | E6: 166.98 | F6: 0 | G6: =SUM(D6:F6) -> 166.98
B7: Abril | C7: 0 | D7: =A7*6% -> 0 | E7: 166.98 | F7: 0 | G7: =SUM(D7:F7) -> 166.98
B8: Maio | C8: 0 | D8: =A8*6% -> 0 | E8: 166.98 | F8: 0 | G8: =SUM(D8:F8) -> 166.98
B9: Junho | C9: 0 | D9: =A9*6% -> 0 | E9: 166.98 | F9: 0 | G9: =SUM(D9:F9) -> 166.98
B10: Julho | C10: 0 | D10: =A10*6% -> 0 | E10: 166.98 | F10: 0 | G10: =SUM(D10:F10) -> 166.98
B11: Agostop | C11: 0 | D11: =A11*6% -> 0 | E11: 0 | F11: 0 | G11: =SUM(D11:F11) -> 0
B12: Setembro | C12: 0 | D12: =A12*6% -> 0 | E12: 0 | F12: 0 | G12: =SUM(D12:F12) -> 0
B13: Outubro | C13: 0 | D13: =A13*6% -> 0 | E13: 0 | F13: 0 | G13: =SUM(D13:F13) -> 0
B14: Novembro | C14: 0 | D14: =A14*6% -> 0 | E14: 0 | F14: 0 | G14: =SUM(D14:F14) -> 0
B15: Dezembro | C15: 0 | D15: =A15*6% -> 0 | E15: 0 | F15: 0 | G15: =SUM(D15:F15) -> 0
B16: TOTAL | C16: =SUM(C4:C15) -> 0 | D16: =SUM(D4:D15) -> 0 | E16: =SUM(E4:E15) -> 1168.86 | F16: =SUM(F4:F15) -> 0 | G16: =SUM(G4:G15) -> 1168.86

Sheet Despesas Lexus
C4: Mês | D4: Contabilidade | E4: Impostos | F4: Pró Labore | G4: Neg. Simples | H4: Neg. INSS | I4: Total Mês
C5: Janeiro | D5: 704 | E5: ='Apurações'!G4 -> 166.98 | F5: 1351.02 | G5: 300 | H5: 500 | I5: =D5+E5+G5+H5 -> 1670.98
C6: Fevereiro | D6: 704 | E6: ='Apurações'!G5 -> 166.98 | F6: 1351.02 | G6: 300 | H6: 500 | I6: =D6+E6+G6+H6 -> 1670.98
C7: Março | D7: 704 | E7: ='Apurações'!G6 -> 166.98 | F7: 1351.02 | G7: 300 | H7: 500 | I7: =D7+E7+G7+H7 -> 1670.98
C8: Abril | D8: 704 | E8: ='Apurações'!G7 -> 166.98 | F8: 1351.02 | G8: 300 | H8: 500 | I8: =D8+E8+G8+H8 -> 1670.98
C9: Maio | D9: 704 | E9: ='Apurações'!G8 -> 166.98 | F9: 1351.02 | G9: 300 | H9: 500 | I9: =D9+E9+G9+H9 -> 1670.98
C10: Junho | D10: 704 | E10: ='Apurações'!G9 -> 166.98 | F10: 1351.02 | G10: 300 | H10: 500 | I10: =D10+E10+G10+H10 -> 1670.98
C11: Julho | D11: 704 | E11: ='Apurações'!G10 -> 166.98 | F11: 1351.02 | G11: 300 | H11: 500 | I11: =D11+E11+G11+H11 -> 1670.98
C12: Agosto | D12: 704 | E12: ='Apurações'!G11 -> 0 | F12: 1351.02 | G12: 300 | H12: 500 | I12: =D12+E12+G12+H12 -> 1504
C13: Setembro | D13: 500 | E13: ='Apurações'!G12 -> 0 | F13: 1351.02 | G13: 300 | H13: 500 | I13: =D13+E13+G13+H13 -> 1300
C14: Outubro | D14: 500 | E14: ='Apurações'!G13 -> 0 | G14: 300 | H14: 500 | I14: =D14+E14+G14+H14 -> 1300
C15: Novembro | D15: 500 | E15: ='Apurações'!G14 -> 0 | G15: 300 | H15: 500 | I15: =D15+E15+G15+H15 -> 1300
C16: Dezembro | D16: 500 | E16: ='Apurações'!G15 -> 0 | G16: 300 | H16: 500 | I16: =D16+E16+G16+H16 -> 1300
