Workbook

Sheet Fast Representações
B1: Nº do Sistema | C1: Cliente | D1: NF | E1: Faturamento | F1: Produto | G1: Valor Unitário | H1: Quantidade | I1: Valor Total | J1: % Comissão | K1: Comissão Bruta | L1: Imposto | M1: Comissão total | N1: Mês a Receber
B2: 8029 | C2: Entrelinhas | D2: 103 | E2: 46183 | F2: Renda 18cm | G2: 41.38 | H2: 3688.2 | I2: =G2*H2 -> 152617.72 | J2: 0.01 | K2: =I2*J2 -> 1526.1772 | L2: =K2*6% -> 91.57063 | M2: =K2-L2 -> 1434.6065 | N2: Julho
B3: 8047 | C3: Belle Fascinio | D3: 118756 | E3: 45992 | F3: Malha Forro | G3: 35.41 | H3: 134.258 | I3: =G3*H3 -> 4754.0758 | J3: 0.015 | K3: =I3*J3 -> 71.311137 | L3: =K3*6% -> 4.2786682 | M3: =K3-L3 -> 67.032468 | N3: Janeiro
B4: 8100 | C4: Be Bless | D4: 171693 | E4: 45993 | F4: Suede Estampado | G4: 28.12 | H4: 100.4 | I4: =G4*H4 -> 2823.248 | J4: 0.02 | K4: =I4*J4 -> 56.46496 | L4: =K4*6% -> 3.3878976 | M4: =K4-L4 -> 53.077062 | N4: Março
B5: 8172 | C5: Irresistivel Lingerie | D5: 119819 | E5: 45671 | F5: Cotton | G5: 39.53 | H5: 614.337 | I5: =G5*H5 -> 24284.742 | J5: 0.015 | K5: =I5*J5 -> 364.27112 | L5: =K5*6% -> 21.856267 | M5: =K5-L5 -> 342.41486 | N5: Fevereiro
B6: Island | C6: Gabriel Rodrigues | D6: 375 | E6: 46044 | F6: Poliamida | G6: 47.9 | H6: 270 | I6: =G6*H6 -> 12933 | J6: 0.02 | K6: =I6*J6 -> 258.66 | L6: =K6*6% -> 15.5196 | M6: =K6-L6 -> 243.1404 | N6: Fevereiro
B7: Island | C7: Gabriel Rodrigues | D7: 381 | E7: 46050 | F7: Romantic | G7: 26 | H7: 37.51 | I7: =G7*H7 -> 975.26 | J7: 0.02 | K7: =I7*J7 -> 19.5052 | L7: =K7*6% -> 1.170312 | M7: =K7-L7 -> 18.334888 | N7: Fevereiro
B8: Island | C8: F7 New Style | D8: 385 | E8: 46056 | F8: Suplex | G8: 23.9 | H8: 37.54 | I8: =G8*H8 -> 897.206 | J8: 0.02 | K8: =I8*J8 -> 17.94412 | L8: =K8*6% -> 1.0766472 | M8: =K8-L8 -> 16.867473 | N8: Abril
B9: Island | C9: Gabriel Rodrigues | D9: 392 | E9: 46063 | F9: Poliamida | G9: 47.9 | H9: 130.23 | I9: =G9*H9 -> 6238.017 | J9: 0.02 | K9: =I9*J9 -> 124.76034 | L9: =K9*6% -> 7.4856204 | M9: =K9-L9 -> 117.27472 | N9: Abril
B10: 8498 | C10: Irresistivel Lingerie | D10: 122409 | E10: 46104 | F10: Cotton | G10: 39.75 | H10: 263.614 | I10: =G10*H10 -> 10478.656 | J10: 0.015 | K10: =I10*J10 -> 157.17985 | L10: =K10*6% -> 9.4307908 | M10: =K10-L10 -> 147.74906 | N10: Maio
B11: 8583 | C11: Belle Sensi | D11: 123271 | E11: 46126 | F11: Cotton | G11: 38.94 | H11: 268.012 | I11: =G11*H11 -> 10436.387 | J11: 0.015 | K11: =I11*J11 -> 156.54581 | L11: =K11*6% -> 9.3927486 | M11: =K11-L11 -> 147.15306 | N11: Maio
B12: 8666 | C12: WWA | D12: 123655 | E12: 46139 | F12: Cotton | G12: 38.65 | H12: 494.492 | I12: =G12*H12 -> 19112.116 | J12: 0.015 | K12: =I12*J12 -> 286.68174 | L12: =K12*6% -> 17.200904 | M12: =K12-L12 -> 269.48083 | N12: Maio
B13: 8726 | C13: D'bellus | D13: 124231 | E13: 46154 | F13: Cotton | G13: 38.48 | H13: 472.169 | I13: =G13*H13 -> 18169.063 | J13: 0.015 | K13: =I13*J13 -> 272.53595 | L13: =K13*6% -> 16.352157 | M13: =K13-L13 -> 256.18379 | N13: Junho
B14: 8732 | C14: Irresistivel Lingerie | D14: 124243 | E14: 46154 | F14: Cotton | G14: 39.55 | H14: 735.421 | I14: =G14*H14 -> 29085.901 | J14: 0.015 | K14: =I14*J14 -> 436.28851 | L14: =K14*6% -> 26.177311 | M14: =K14-L14 -> 410.1112 | N14: Junho
B15: 8770 | C15: Mavique | D15: 124688 | E15: 46164 | F15: Cotton | G15: 38.6 | H15: 138.886 | I15: =G15*H15 -> 5360.9996 | J15: 0.015 | K15: =I15*J15 -> 80.414994 | L15: =K15*6% -> 4.8248996 | M15: =K15-L15 -> 75.590094 | N15: Junho
B16: 9000 | C16: Entrelinhas | D16: 106 | E16: 46183 | F16: Renda 18cm | G16: 41.66 | H16: 903.5 | I16: =G16*H16 -> 37639.81 | J16: 0.01 | K16: =I16*J16 -> 376.3981 | L16: =K16*6% -> 22.583886 | M16: =K16-L16 -> 353.81421 | N16: Julho
B17: 8900 | C17: Gabriel Rodrigues | D17: ------ | E17: 46195 | F17: LD Romantic | G17: 25 | H17: 283.29 | I17: =G17*H17 -> 7082.25 | J17: 0.02 | K17: =I17*J17 -> 141.645 | L17: =K17*6% -> 8.4987 | M17: =K17-L17 -> 133.1463 | N17: Julho
B18: 8950 | C18: Gabriel Rodrigues | D18: ------ | E18: 46203 | F18: LD Romantic | G18: 25 | H18: 75.85 | I18: =G18*H18 -> 1896.25 | J18: 0.02 | K18: =I18*J18 -> 37.925 | L18: =K18*6% -> 2.2755 | M18: =K18-L18 -> 35.6495 | N18: Agosto
B19: 9022 | C19: Mavique | D19: 126865 | E19: 46224 | F19: Cotton | G19: 38.86 | H19: 154.764 | I19: =G19*H19 -> 6014.129 | J19: 0.015 | K19: =I19*J19 -> 90.211936 | L19: =K19*6% -> 5.4127161 | M19: =K19-L19 -> 84.799219 | N19: Agosto
B20: 9045 | C20: Gabriel Rodrigues | D20: ND | E20: 46224 | F20: LD Romantic | G20: 22 | H20: 508.69 | I20: =G20*H20 -> 11191.18 | J20: 0.02 | K20: =I20*J20 -> 223.8236 | L20: =K20*6% -> 13.429416 | M20: =K20-L20 -> 210.39418 | N20: Agosto
B21: 9067 | C21: Gabriel Rodrigues | D21: ND | E21: 46230 | F21: LD Romantic | G21: 22 | H21: 55.63 | I21: =G21*H21 -> 1223.86 | J21: 0.02 | K21: =I21*J21 -> 24.4772 | L21: =K21*6% -> 1.468632 | M21: =K21-L21 -> 23.008568 | N21: Agosto
B22: 9138 | C22: WWA | D22: 127699 | E22: 46246 | F22: Cotton | G22: 38.66 | H22: 527.369 | I22: =G22*H22 -> 20388.086 | J22: 0.015 | K22: =I22*J22 -> 305.82128 | L22: =K22*6% -> 18.349277 | M22: =K22-L22 -> 287.47201 | N22: Setembro
B23: 9194 | C23: Mavique | D23: 128109 | E23: 46255 | F23: Cotton | G23: 39.59 | H23: 161.477 | I23: =G23*H23 -> 6392.8744 | J23: 0.015 | K23: =I23*J23 -> 95.893116 | L23: =K23*6% -> 5.753587 | M23: =K23-L23 -> 90.139529 | N23: Setembro
G24: 0 | I24: =G24*H24 -> 0 | K24: =I24*J24 -> 0 | L24: =K24*6% -> 0 | M24: =K24-L24 -> 0
G25: 0 | I25: =G25*H25 -> 0 | K25: =I25*J25 -> 0 | L25: =K25*6% -> 0 | M25: =K25-L25 -> 0
G26: 0 | I26: =G26*H26 -> 0 | K26: =I26*J26 -> 0 | L26: =K26*6% -> 0 | M26: =K26-L26 -> 0
G27: 0 | I27: =G27*H27 -> 0 | K27: =I27*J27 -> 0 | L27: =K27*6% -> 0 | M27: =K27-L27 -> 0
G28: 0 | I28: =G28*H28 -> 0 | K28: =I28*J28 -> 0 | L28: =K28*6% -> 0 | M28: =K28-L28 -> 0
G29: 0 | I29: =G29*H29 -> 0 | K29: =I29*J29 -> 0 | L29: =K29*6% -> 0 | M29: =K29-L29 -> 0
G30: 0 | I30: =G30*H30 -> 0 | K30: =I30*J30 -> 0 | L30: =K30*6% -> 0 | M30: =K30-L30 -> 0
G31: 0 | I31: =G31*H31 -> 0 | K31: =I31*J31 -> 0 | L31: =K31*6% -> 0 | M31: =K31-L31 -> 0
G32: 0 | I32: =G32*H32 -> 0 | K32: =I32*J32 -> 0 | L32: =K32*6% -> 0 | M32: =K32-L32 -> 0
G33: 0 | I33: =G33*H33 -> 0 | K33: =I33*J33 -> 0 | L33: =K33*6% -> 0 | M33: =K33-L33 -> 0
G34: 0 | I34: =G34*H34 -> 0 | K34: =I34*J34 -> 0 | L34: =K34*6% -> 0 | M34: =K34-L34 -> 0
G35: 0 | I35: =G35*H35 -> 0 | K35: =I35*J35 -> 0 | L35: =K35*6% -> 0 | M35: =K35-L35 -> 0
... G922: 0 | I922: =G922*H922 -> 0 | K922: =I922*J922 -> 0 | L922: =K922*6% -> 0 | M922: =K922-L922 -> 0
G923: 0 | I923: =G923*H923 -> 0 | K923: =I923*J923 -> 0 | M923: =K923-L923 -> 0
G924: 0 | I924: =G924*H924 -> 0 | K924: =I924*J924 -> 0 | M924: =K924-L924 -> 0
G925: 0 | I925: =G925*H925 -> 0 | K925: =I925*J925 -> 0 | M925: =K925-L925 -> 0
G926: 0 | I926: =G926*H926 -> 0 | K926: =I926*J926 -> 0 | M926: =K926-L926 -> 0

Sheet Fast Malhas
A1: o | B1: Nº Processo | C1: Cliente | D1: Custo | E1: Quantidade | F1: Valor Total | G1: % Comissão | H1: Comissão | I1: Mês a Receber
B2: 1822 | C2: Entrelinhas | D2: 45.41 | E2: 2989.4 | F2: =D2*E2 -> 135748.65 | G2: 0.01 | H2: =F2*G2 -> 1357.4865 | I2: Janeiro
B3: 1995 | C3: Kelly Cristina | D3: 27.89 | E3: 5357.27 | F3: =D3*E3 -> 149414.26 | G3: 0.01 | H3: =F3*G3 -> 1494.1426 | I3: Janeiro
B4: 2018 | C4: Jóia | D4: 26.35 | E4: 2035.15 | F4: =D4*E4 -> 53626.202 | G4: 0.01 | H4: =F4*G4 -> 536.26202 | I4: Janeiro
B5: 2070 | C5: Kelly Cristina | D5: 27.05 | E5: 5280 | F5: =D5*E5 -> 142824 | G5: 0.01 | H5: =F5*G5 -> 1428.24 | I5: Março
B6: 2089 | C6: Kelly Cristina | D6: 26.46 | E6: 2120.18 | F6: =D6*E6 -> 56099.963 | G6: 0.01 | H6: =F6*G6 -> 560.99963 | I6: Janeiro
B7: 2131 | C7: Jóia | D7: 24.24 | E7: 2973.28 | F7: =D7*E7 -> 72072.307 | G7: 0.01 | H7: =F7*G7 -> 720.72307 | I7: Janeiro
B8: 2174 | C8: Entrelinhas | D8: 46.02 | E8: 1675.26 | F8: =D8*E8 -> 77095.465 | G8: 0.01 | H8: =F8*G8 -> 770.95465 | I8: Janeiro
B9: 2175 | C9: Kelly Cristina | D9: 26.01 | E9: 2511.75 | F9: =D9*E9 -> 65330.618 | G9: 0.01 | H9: =F9*G9 -> 653.30618 | I9: Janeiro
B10: 2176 | C10: Kelly Cristina | D10: 25.67 | E10: 2460.07 | F10: =D10*E10 -> 63149.997 | G10: 0.01 | H10: =F10*G10 -> 631.49997 | I10: Janeiro
B11: 2196 | C11: Entrelinhas | D11: 44.94 | E11: 5911.91 | F11: =D11*E11 -> 265681.24 | G11: 0.01 | H11: =F11*G11 -> 2656.8124 | I11: Fevereiro
B12: 2211 | C12: Entrelinhas | D12: 25.07 | E12: 3963.46 | F12: =D12*E12 -> 99363.942 | G12: 0.01 | H12: =F12*G12 -> 993.63942 | I12: Fevereiro
B13: 2212 | C13: Entrelinhas | D13: 24.68 | E13: 3892.27 | F13: =D13*E13 -> 96061.224 | G13: 0.01 | H13: =F13*G13 -> 960.61224 | I13: Fevereiro
... B54: 2517 | C54: Entrelinhas | D54: 46.35 | E54: 2959.2 | F54: =D54*E54 -> 137158.92 | G54: 0.01 | H54: =F54*G54 -> 1371.5892 | I54: Junho
B55: 2527 | C55: Entrelinhas | D55: 46 | E55: 3969 | F55: =D55*E55 -> 182574 | G55: 0.01 | H55: =F55*G55 -> 1825.74
B56: 2529 | C56: Entrelinhas | D56: 28.73 | E56: 3831.4 | F56: =D56*E56 -> 110076.12 | G56: 0.01 | H56: =F56*G56 -> 1100.7612 | I56: Agosto
B57: 2530 | C57: Entrelinhas | D57: 28.08 | E57: 3219.13 | F57: =D57*E57 -> 90393.17 | G57: 0.01 | H57: =F57*G57 -> 903.9317 | I57: Setembro
B58: 2532 | C58: Entrelinhas | D58: 46.74 | E58: 5009.27 | F58: =D58*E58 -> 234133.28 | G58: 0.01 | H58: =F58*G58 -> 2341.3328 | I58: Agosto
B59: 2552 | C59: Entrelinhas | D59: 45.29 | E59: 4904.85 | F59: =D59*E59 -> 222140.66 | G59: 0.01 | H59: =F59*G59 -> 2221.4066 | I59: Agosto
B60: 2553 | C60: Entrelinhas | D60: 46 | E60: 5000 | F60: =D60*E60 -> 230000 | G60: 0.01 | H60: =F60*G60 -> 2300
B61: 2564 | C61: Joia Íntima | D61: 27.72 | E61: 2046.83 | F61: =D61*E61 -> 56738.128 | G61: 0.01 | H61: =F61*G61 -> 567.38128 | I61: Julho
B62: 2565 | C62: Joia Íntima | D62: 28.71 | E62: 5082.64 | F62: =D62*E62 -> 145922.59 | G62: 0.01 | H62: =F62*G62 -> 1459.2259 | I62: Agosto
B63: 2571 | C63: Kelly Cristina | D63: 29.63 | E63: 7105.71 | F63: =D63*E63 -> 210542.19 | G63: 0.01 | H63: =F63*G63 -> 2105.4219 | I63: Agosto
B64: 2596 | C64: Entrelinhas | D64: 28.7 | E64: 3000 | F64: =D64*E64 -> 86100 | G64: 0.01 | H64: =F64*G64 -> 861
B65: 2612 | C65: Entrelinhas | D65: 28.06 | E65: 4979.13 | F65: =D65*E65 -> 139714.39 | G65: 0.01 | H65: =F65*G65 -> 1397.1439 | I65: Setembro
B66: 2614 | C66: Entrelinhas | D66: 27 | E66: 5000 | F66: =D66*E66 -> 135000 | G66: 0.01 | H66: =F66*G66 -> 1350
B67: 2616 | C67: Entrelinhas | D67: 27.98 | E67: 4950.02 | F67: =D67*E67 -> 138501.56 | G67: 0.01 | H67: =F67*G67 -> 1385.0156 | I67: Setembro
B68: 2630 | C68: F7 New Style | D68: 26.99 | E68: 2831.99 | F68: =D68*E68 -> 76435.41 | G68: 0.01 | H68: =F68*G68 -> 764.3541 | I68: Setembro
B69: 2635 | C69: Gabriel Rodrigues | D69: 27.6 | E69: 1148 | F69: =D69*E69 -> 31684.8 | G69: 0.01 | H69: =F69*G69 -> 316.848 | I69: Agosto
B70: 2666 | C70: Entrelinhas | D70: 26.5 | E70: 4000 | F70: =D70*E70 -> 106000 | G70: 0.01 | H70: =F70*G70 -> 1060
B71: 2672 | C71: Entrelinhas | D71: 26.5 | E71: 5040 | F71: =D71*E71 -> 133560 | G71: 0.01 | H71: =F71*G71 -> 1335.6
B72: 2678 | C72: Kelly Cristina | D72: 28.73 | E72: 3528 | F72: =D72*E72 -> 101359.44 | G72: 0.01 | H72: =F72*G72 -> 1013.5944
B73: 2677 | C73: Kelly Cristina | D73: 28.73 | E73: 3528 | F73: =D73*E73 -> 101359.44 | G73: 0.01 | H73: =F73*G73 -> 1013.5944
B74: 2694 | C74: Gabriel Rodrigues | D74: 27.94 | E74: 2400 | F74: =D74*E74 -> 67056 | G74: 0.01 | H74: =F74*G74 -> 670.56
B75: 2695 | C75: Entrelinhas | D75: 27 | E75: 5000 | F75: =D75*E75 -> 135000 | G75: 0.01 | H75: =F75*G75 -> 1350
B76: 2702 | C76: Entrelinhas | D76: 46 | E76: 5000 | F76: =D76*E76 -> 230000 | G76: 0.01 | H76: =F76*G76 -> 2300
B77: 2720 | C77: F7 New Style | D77: 28.73 | E77: 4500 | F77: =D77*E77 -> 129285 | G77: 0.01 | H77: =F77*G77 -> 1292.85
B78: 2725 | C78: Entrelinhas | D78: 26.5 | E78: 3400 | F78: =D78*E78 -> 90100 | G78: 0.01 | H78: =F78*G78 -> 901
B79: 2726 | C79: Entrelinhas | D79: 26.5 | E79: 3400 | F79: =D79*E79 -> 90100 | G79: 0.01 | H79: =F79*G79 -> 901
B80: 2744 | C80: Entrelinhas | D80: 49 | E80: 3800 | F80: =D80*E80 -> 186200 | G80: 0.01 | H80: =F80*G80 -> 1862
...

Sheet Fast Elásticos
A1: Nº Pedido | B1: Cliente | C1: Nota Fiscal | D1: Faturamento | E1: Data de Pagamento | F1: Valor Unitário | G1: Quantidade | H1: Valor Total | I1: % Comissão | J1: Comissão | K1: Mês a Receber
A2: 8117 | B2: F7 New Style | C2: 30634 | D2: 46001 | E2: 46001 | F2: 11.7 | G2: 180 | H2: =F2*G2 -> 2106 | I2: 0.02 | J2: =H2*I2 -> 42.12 | K2: Janeiro
A3: 8171 | B3: Miranda e Fraga | C3: 30737 | D3: 46042 | F3: 11.7 | G3: 72 | H3: =F3*G3 -> 842.4 | I3: 0.02 | J3: =H3*I3 -> 16.848 | K3: Fevereiro
A4: 8171 | B4: Miranda e Fraga | C4: 30737 | D4: 46042 | F4: 8.9 | G4: 72 | H4: =F4*G4 -> 640.8 | I4: 0.02 | J4: =H4*I4 -> 12.816 | K4: Fevereiro
A5: 8294 | B5: Siqueira | C5: 30949 | D5: 46077 | F5: 11.7 | G5: 2280 | H5: =F5*G5 -> 26676 | I5: 0.02 | J5: =H5*I5 -> 533.52 | K5: Fevereiro
A6: 8304 | B6: F7 New Style | C6: 30819 | D6: 46057 | F6: 11.7 | G6: 240 | H6: =F6*G6 -> 2808 | I6: 0.02 | J6: =H6*I6 -> 56.16 | K6: Fevereiro
A7: 8336 | B7: Gabriel | C7: 30848 | D7: 46059 | F7: 11.7 | G7: 84 | H7: =F7*G7 -> 982.8 | I7: 0.02 | J7: =H7*I7 -> 19.656 | K7: Março
A8: 8414 | B8: Miranda e Fraga | C8: 31119 | D8: 46097 | F8: 11.7 | G8: 0 | H8: =F8*G8 -> 0 | I8: 0.02 | J8: =H8*I8 -> 0 | K8: Março
A9: 8486 | B9: Mauricio | C9: 31329 | D9: 46134 | F9: 11.7 | G9: 84 | H9: =F9*G9 -> 982.8 | I9: 0.02 | J9: =H9*I9 -> 19.656 | K9: Maio
A10: 8633 | B10: Miranda e Fraga | C10: 31330 | F10: 12.9 | G10: 0 | H10: =F10*G10 -> 0 | I10: 0.02 | J10: =H10*I10 -> 0 | K10: Maio
A11: 8753 | B11: Miranda e Fraga | C11: 31481 | D11: 46163 | F11: 12.9 | G11: 144 | H11: =F11*G11 -> 1857.6 | I11: 0.02 | J11: =H11*I11 -> 37.152 | K11: Junho
A12: 8910 | B12: Miranda e Fraga | C12: 31679 | D12: 46202 | F12: 12.9 | G12: 192 | H12: =F12*G12 -> 2476.8 | I12: 0.02 | J12: =H12*I12 -> 49.536 | K12: Julho
A13: 9054 | B13: Miranda e Fraga | C13: 31838 | D13: 46233 | E13: 46246 | F13: 12.9 | G13: 156 | H13: =F13*G13 -> 2012.4 | I13: 0.02 | J13: =H13*I13 -> 40.248 | K13: Agosto
G14: 0 | H14: =F14*G14 -> 0 | I14: 0.02 | J14: =H14*I14 -> 0
G15: 0 | H15: =F15*G15 -> 0 | I15: 0.02 | J15: =H15*I15 -> 0
G16: 0 | H16: =F16*G16 -> 0 | I16: 0.02 | J16: =H16*I16 -> 0
G17: 0 | H17: =F17*G17 -> 0 | I17: 0.02 | J17: =H17*I17 -> 0
G18: 0 | H18: =F18*G18 -> 0 | I18: 0.02 | J18: =H18*I18 -> 0
G19: 0 | H19: =F19*G19 -> 0 | I19: 0.02 | J19: =H19*I19 -> 0
G20: 0 | H20: =F20*G20 -> 0 | I20: 0.02 | J20: =H20*I20 -> 0
G21: 0 | H21: =F21*G21 -> 0 | I21: 0.02 | J21: =H21*I21 -> 0
G22: 0 | H22: =F22*G22 -> 0 | I22: 0.02 | J22: =H22*I22 -> 0
G23: 0 | H23: =F23*G23 -> 0 | I23: 0.02 | J23: =H23*I23 -> 0
G24: 0 | H24: =F24*G24 -> 0 | I24: 0.02 | J24: =H24*I24 -> 0
G25: 0 | H25: =F25*G25 -> 0 | I25: 0.02 | J25: =H25*I25 -> 0
... G65: 0 | H65: =F65*G65 -> 0 | I65: 0.02 | J65: =H65*I65 -> 0

Sheet Fast Conselheiro
B1: Data de entrada | C1: Nº do Pedido | D1: Cliente | E1: Produto | F1: Preço | G1: Quantidade | H1: Valor Total | I1: Status | J1: % Comissão | K1: Comissão total | L1: Mês a Receber
B2: 46237 | C2: 418AFDA9 | D2: MS Fabulosa | E2: Romantic | F2: 29.9 | G2: 300 | H2: =F2*G2 -> 8970 | I2: Pago | J2: 0.02 | K2: =H2*J2 -> 179.4 | L2: Setembro
B3: 46244 | C3: 1622AB33 | D3: Micael | E3: Suplex Zero | F3: 37.9 | G3: 19.96 | H3: =F3*G3 -> 756.484 | I3: Pago | J3: 0.02 | K3: =H3*J3 -> 15.12968 | L3: Setembro
B4: 46246 | C4: B67B0E49/E68A6EAE | D4: NovaMoon | E4: Romantic | F4: 29.9 | G4: 1835.57 | H4: =F4*G4 -> 54883.543 | I4: Pago | J4: 0.02 | K4: =H4*J4 -> 1097.6709 | L4: Setembro
B5: 46246 | D5: Nicoly CS | E5: Romantic | F5: 28.9 | G5: 113.91 | H5: =F5*G5 -> 3291.999 | I5: Pago | J5: 0.02 | K5: =H5*J5 -> 65.83998 | L5: Setembro
B6: 46246 | C6: DA700ECC | D6: MS Fabulosa | E6: Romantic | F6: 28.9 | G6: 290 | H6: =F6*G6 -> 8381 | I6: Pago | J6: 0.02 | K6: =H6*J6 -> 167.62 | L6: Setembro
B7: 46247 | C7: 388D4F41 | D7: Bellamour | E7: Suplex Zero | F7: 38.9 | G7: 20 | H7: =F7*G7 -> 778 | I7: Pago | J7: 0.02 | K7: =H7*J7 -> 15.56 | L7: Setembro
D8: Gabriel Rodrigues | E8: Poliamida | F8: 54.9 | G8: 60 | H8: =F8*G8 -> 3294 | I8: Pago | J8: 0.02 | K8: =H8*J8 -> 65.88 | L8: Setembro
B9: 46253 | D9: Micael | E9: Suplex Zero | F9: 37.9 | G9: 20 | H9: =F9*G9 -> 758 | I9: Aguardando Pagamento | J9: 0.02 | K9: =H9*J9 -> 15.16
B10: 46253 | D10: MS Fabulosa | E10: Romantic | F10: 28.9 | G10: 230 | H10: =F10*G10 -> 6647 | I10: Pago | J10: 0.02 | K10: =H10*J10 -> 132.94 | L10: Setembro
B11: 46253 | D11: BR Acessórios | E11: Romantic | F11: 28.9 | G11: 37 | H11: =F11*G11 -> 1069.3 | I11: Pago | J11: 0.02 | K11: =H11*J11 -> 21.386 | L11: Setembro
D12: Reivax | E12: Romantic | F12: 28.9 | G12: 77.72 | H12: =F12*G12 -> 2246.108 | I12: Pago | J12: 0.02 | K12: =H12*J12 -> 44.92216 | L12: Setembro
H13: =F13*G13 -> 0 | K13: =H13*J13 -> 0
H14: =F14*G14 -> 0 | K14: =H14*J14 -> 0
H15: =F15*G15 -> 0 | K15: =H15*J15 -> 0
H16: =F16*G16 -> 0 | K16: =H16*J16 -> 0
H17: =F17*G17 -> 0 | K17: =H17*J17 -> 0
H18: =F18*G18 -> 0 | K18: =H18*J18 -> 0
H19: =F19*G19 -> 0 | K19: =H19*J19 -> 0
H20: =F20*G20 -> 0 | K20: =H20*J20 -> 0
H21: =F21*G21 -> 0 | K21: =H21*J21 -> 0
H22: =F22*G22 -> 0 | K22: =H22*J22 -> 0
H23: =F23*G23 -> 0 | K23: =H23*J23 -> 0
H24: =F24*G24 -> 0 | K24: =H24*J24 -> 0
... H39: =F39*G39 -> 0 | K39: =H39*J39 -> 0
A40: 2025 | H40: =F40*G40 -> 0 | K40: =H40*J40 -> 0
H41: =F41*G41 -> 0 | K41: =H41*J41 -> 0
H42: =F42*G42 -> 0 | K42: =H42*J42 -> 0
H43: =F43*G43 -> 0 | K43: =H43*J43 -> 0
H44: =F44*G44 -> 0 | K44: =H44*J44 -> 0
H45: =F45*G45 -> 0 | K45: =H45*J45 -> 0
H46: =F46*G46 -> 0 | K46: =H46*J46 -> 0
H47: =F47*G47 -> 0 | K47: =H47*J47 -> 0
H48: =F48*G48 -> 0 | K48: =H48*J48 -> 0
H49: =F49*G49 -> 0 | K49: =H49*J49 -> 0
H50: =F50*G50 -> 0 | K50: =H50*J50 -> 0
H51: =F51*G51 -> 0 | K51: =H51*J51 -> 0
H52: =F52*G52 -> 0 | K52: =H52*J52 -> 0
... H902: =F902*G902 -> 0 | K902: =H902*J902 -> 0

Sheet RM Têxtil
A1: ]]]]]]]]] | B1: Data de entrada | C1: Nº do Pedido | D1: Cliente | E1: Produto | F1: Preço | G1: Quantidade | H1: Valor Total | I1: Status | J1: % Comissão | K1: Comissão total | L1: Mês a Receber
B2: 46383 | D2: Gabriel Rodrigues | E2: Viés 16mm Pue | F2: 16 | G2: 426 | H2: =F2*G2 -> 6816 | I2: Pago | J2: 0.01 | K2: =H2*J2 -> 68.16 | L2: Janeiro
B3: 46383 | D3: Gabriel Rodrigues | E3: Viés 25mm Pue | F3: 14.5 | G3: 220 | H3: =F3*G3 -> 3190 | I3: Pago | J3: 0.01 | K3: =H3*J3 -> 31.9 | L3: Janeiro
B4: 46027 | C4: S/N | D4: F7 New Style | E4: Romantic | F4: 27.9 | G4: 84.46 | H4: =F4*G4 -> 2356.434 | I4: Pago | J4: 0.01 | K4: =H4*J4 -> 23.56434 | L4: Fevereiro
B5: 46035 | C5: S/N | D5: Auvo | E5: Romantic | F5: 27.9 | G5: 340 | H5: =F5*G5 -> 9486 | I5: Pago | J5: 0.01 | K5: =H5*J5 -> 94.86 | L5: Fevereiro
B6: 46029 | C6: 2006 | D6: Gabriel Rodrigues | E6: Viés 16mm Pue | F6: 16 | G6: 240 | H6: =F6*G6 -> 3840 | I6: Pago | J6: 0.02 | K6: =H6*J6 -> 76.8 | L6: Fevereiro
B7: 46044 | D7: Auvo | E7: Romantic | F7: 27.9 | G7: 1087.1 | H7: =F7*G7 -> 30330.09 | I7: Pago | J7: 0.01 | K7: =H7*J7 -> 303.3009 | L7: Janeiro
B8: 46113 | C8: 5 | D8: MS Fabulosa | E8: Romantic | F8: 27.9 | G8: 364.49 | H8: =F8*G8 -> 10169.271 | I8: Pago | J8: 0.02 | K8: =H8*J8 -> 203.38542 | L8: Maio
B9: 46120 | D9: MS Fabulosa | E9: Romantic | F9: 28.9 | G9: 215.43 | H9: =F9*G9 -> 6225.927 | I9: Pago | J9: 0.02 | K9: =H9*J9 -> 124.51854 | L9: Maio
B10: 46121 | D10: BR Acessórios | E10: Romantic | F10: 29.9 | G10: 116.87 | H10: =F10*G10 -> 3494.413 | I10: Pago | J10: 0.02 | K10: =H10*J10 -> 69.88826 | L10: Junho
B11: 46125 | D11: BR Acessórios | E11: Romantic | F11: 29.9 | G11: 170 | H11: =F11*G11 -> 5083 | I11: Pago | J11: 0.02 | K11: =H11*J11 -> 101.66 | L11: Junho
B12: 46139 | D12: MS Fabulosa | E12: Romantic | F12: 29.8 | G12: 53.24 | H12: =F12*G12 -> 1586.552 | I12: Pago | J12: 0.02 | K12: =H12*J12 -> 31.73104 | L12: Maio
B13: 46161 | D13: BR Acessórios | E13: Romantic | F13: 29.9 | G13: 437.35 | H13: =F13*G13 -> 13076.765 | I13: Aguardando Pagamento | J13: 0.02 | K13: =H13*J13 -> 261.5353
B14: 46168 | D14: MS Fabulosa | E14: Romantic | F14: 29.9 | G14: 327.79 | H14: =F14*G14 -> 9800.921 | I14: Pago | J14: 0.02 | K14: =H14*J14 -> 196.01842 | L14: Junho
B15: 46181 | D15: Kelly Cristina | E15: Romantic | F15: 29.8 | G15: 525.81 | H15: =F15*G15 -> 15669.138 | I15: Pago | J15: 0.02 | K15: =H15*J15 -> 313.38276 | L15: Julho
B16: 46181 | D16: MS Fabulosa | E16: Romantic | F16: 29.8 | G16: 380.53 | H16: =F16*G16 -> 11339.794 | I16: Pago | J16: 0.02 | K16: =H16*J16 -> 226.79588 | L16: Julho
B17: 46185 | D17: Kelly Cristina | E17: Romantic | F17: 29.8 | G17: 526.59 | H17: =F17*G17 -> 15692.382 | I17: Pago | J17: 0.02 | K17: =H17*J17 -> 313.84764 | L17: Junho
B18: 46189 | D18: Gabriel Rodrigues | E18: Romantic | F18: 29.9 | G18: 630.69 | H18: =F18*G18 -> 18857.631 | I18: Pago | J18: 0.02 | K18: =H18*J18 -> 377.15262 | L18: Agosto
B19: 46190 | D19: BR Acessórios | E19: Romantic | F19: 29.9 | G19: 379.5 | H19: =F19*G19 -> 11347.05 | I19: Aguardando Pagamento | J19: 0.02 | K19: =H19*J19 -> 226.941
B20: 46191 | D20: Kelly Cristina | E20: Romantic | F20: 29.8 | G20: 526.56 | H20: =F20*G20 -> 15691.488 | I20: Pago | J20: 0.02 | K20: =H20*J20 -> 313.82976 | L20: Julho
B21: 46210 | D21: MS Fabulosa | E21: Romantic | F21: 29.9 | G21: 310.33 | H21: =F21*G21 -> 9278.867 | I21: Pago | J21: 0.02 | K21: =H21*J21 -> 185.57734 | L21: Agosto
B22: 46211 | D22: MS Fabulosa | E22: Romantic | F22: 29.9 | G22: 35.66 | H22: =F22*G22 -> 1066.234 | I22: Pago | J22: 0.02 | K22: =H22*J22 -> 21.32468 | L22: Agosto
B23: 46216 | D23: BR Acessórios | E23: Romantic | F23: 29.9 | G23: 368.16 | H23: =F23*G23 -> 11007.984 | I23: Aguardando Pagamento | J23: 0.02 | K23: =H23*J23 -> 220.15968
B24: 6693637 | D24: MS Fabulosa | E24: Romantic | F24: 29.9 | G24: 375.19 | H24: =F24*G24 -> 11218.181 | I24: Pago | J24: 0.02 | K24: =H24*J24 -> 224.36362 | L24: Agosto
B25: 46213 | D25: Boxer | E25: Boxer | F25: 41.9 | G25: 300 | H25: =F25*G25 -> 12570 | I25: Aguardando Pagamento | J25: 0.01 | K25: =H25*J25 -> 125.7
B26: 46233 | D26: Kelly Cristina | E26: Romantic | F26: 29.9 | G26: 105.82 | H26: =F26*G26 -> 3164.018 | I26: Pago | J26: 0.02 | K26: =H26*J26 -> 63.28036 | L26: Agosto
B27: 46233 | D27: Valéria | E27: Romantic | F27: 29.9 | G27: 35.7 | H27: =F27*G27 -> 1067.43 | I27: Aguardando Pagamento | J27: 0.02 | K27: =H27*J27 -> 21.3486 | L27: Setembro
B28: 46233 | D28: Valéria | E28: Romantic | F28: 54.9 | G28: 14.09 | H28: =F28*G28 -> 773.541 | I28: Aguardando Pagamento | J28: 0.02 | K28: =H28*J28 -> 15.47082 | L28: Setembro
B29: 46235 | D29: BR Acessórios | E29: Romantic | F29: 29.9 | G29: 348.38 | H29: =F29*G29 -> 10416.562 | I29: Aguardando Pagamento | J29: 0.02 | K29: =H29*J29 -> 208.33124
B30: 46238 | D30: MS Fabulosa | E30: Romantic | F30: 29.9 | G30: 54.63 | H30: =F30*G30 -> 1633.437 | I30: Aguardando Pagamento | J30: 0.02 | K30: =H30*J30 -> 32.66874 | L30: Setembro
H31: =F31*G31 -> 0 | K31: =H31*J31 -> 0
H32: =F32*G32 -> 0 | K32: =H32*J32 -> 0
H33: =F33*G33 -> 0 | K33: =H33*J33 -> 0
H34: =F34*G34 -> 0 | K34: =H34*J34 -> 0
H35: =F35*G35 -> 0 | K35: =H35*J35 -> 0
H36: =F36*G36 -> 0 | K36: =H36*J36 -> 0
H37: =F37*G37 -> 0 | K37: =H37*J37 -> 0
H38: =F38*G38 -> 0 | K38: =H38*J38 -> 0
H39: =F39*G39 -> 0 | K39: =H39*J39 -> 0
H40: =F40*G40 -> 0 | K40: =H40*J40 -> 0
...

Sheet 2R Representações
B1: Data de entrada | C1: Nota Fiscal | D1: Cliente | E1: Produto | F1: Preço | G1: Quantidade | H1: Valor Total | I1: Status | J1: % Comissão | K1: Comissão total | L1: Mês a Receber
B2: 45995 | C2: 180878 | D2: Auvo | E2: Suplex | F2: 28.9 | G2: 1621.88 | H2: =F2*G2 -> 46872.332 | I2: Faturado | J2: 0.0075 | K2: =H2*J2 -> 351.54249 | L2: Janeiro
B3: 45995 | C3: 180716 | D3: Auvo | E3: Suplex | F3: 28.9 | G3: 234.581 | H3: =F3*G3 -> 6779.3909 | I3: Faturado | J3: 0.0075 | K3: =H3*J3 -> 50.845432 | L3: Janeiro
B4: 45999 | C4: 101634 | D4: Gabriel Rodrigues | E4: Suede Canelado | F4: 26.9 | G4: 234.9 | H4: =F4*G4 -> 6318.81 | I4: Faturado | J4: 0.025 | K4: =H4*J4 -> 157.97025 | L4: Janeiro
B5: 45999 | C5: 10079 | D5: Auvo | E5: Suplex Iron | F5: 44.9 | G5: 115.06 | H5: =F5*G5 -> 5166.194 | I5: Faturado | J5: 0.0075 | K5: =H5*J5 -> 38.746455 | L5: Janeiro
B6: 46000 | C6: 122911 | D6: Siqueira | E6: Galena | F6: 3.7 | G6: 813.51 | H6: =F6*G6 -> 3009.987 | I6: Faturado | J6: 0.01 | K6: =H6*J6 -> 30.09987 | L6: Janeiro
B7: 46000 | C7: 122921 | D7: Siqueira | E7: Galena | F7: 3.7 | G7: 697.297 | H7: =F7*G7 -> 2579.9989 | I7: Faturado | J7: 0.01 | K7: =H7*J7 -> 25.799989 | L7: Janeiro
B8: 46007 | C8: 10105 | D8: Auvo | E8: Suplex Iron | F8: 44.9 | G8: 1172.4 | H8: =F8*G8 -> 52640.76 | I8: Faturado | J8: 0.005 | K8: =H8*J8 -> 263.2038 | L8: Janeiro
B9: 46007 | C9: 123071 | D9: Siqueira | E9: Galena | F9: 3.7 | G9: 3835.13 | H9: =F9*G9 -> 14189.981 | I9: Faturado | J9: 0.01 | K9: =H9*J9 -> 141.89981 | L9: Janeiro
B10: 46008 | C10: 10114 | D10: Auvo | E10: Suplex Iron | F10: 44.9 | G10: 700.66 | H10: =F10*G10 -> 31459.634 | I10: Faturado | J10: 0.005 | K10: =H10*J10 -> 157.29817 | L10: Janeiro
B11: 46009 | C11: 123361 | D11: Siqueira | E11: Galena | F11: 3.7 | G11: 2324.32 | H11: =F11*G11 -> 8599.984 | I11: Faturado | J11: 0.01 | K11: =H11*J11 -> 85.99984 | L11: Janeiro
C12: 12414 | D12: Siqueira | E12: Galena | F12: 4.3 | G12: 240 | H12: =F12*G12 -> 1032 | I12: Faturado | J12: 0.01 | K12: =H12*J12 -> 10.32 | L12: Março
C13: 12414 | D13: Siqueira | E13: Galena | F13: 4.3 | G13: 480 | H13: =F13*G13 -> 2064 | I13: Faturado | J13: 0.01 | K13: =H13*J13 -> 20.64 | L13: Abril
C14: 12414 | D14: Siqueira | E14: Galena | F14: 4.3 | G14: 480 | H14: =F14*G14 -> 2064 | I14: Faturado | J14: 0.01 | K14: =H14*J14 -> 20.64 | L14: Maio
B15: 46050 | D15: Auvo | E15: Suplex Iron | F15: 42.9 | G15: 960 | H15: =F15*G15 -> 41184 | I15: Faturado | J15: 0.0075 | K15: =H15*J15 -> 308.88 | L15: Abril
D16: Multiplas | E16: vendas | F16: 80 | G16: 1000 | H16: =F16*G16 -> 80000 | I16: Faturado | J16: 0.0125 | K16: =H16*J16 -> 1000 | L16: Junho
H17: =F17*G17 -> 0 | K17: =H17*J17 -> 0
H18: =F18*G18 -> 0 | K18: =H18*J18 -> 0
H19: =F19*G19 -> 0 | K19: =H19*J19 -> 0
H20: =F20*G20 -> 0 | K20: =H20*J20 -> 0
H21: =F21*G21 -> 0 | K21: =H21*J21 -> 0
H22: =F22*G22 -> 0 | K22: =H22*J22 -> 0
H23: =F23*G23 -> 0 | K23: =H23*J23 -> 0
H24: =F24*G24 -> 0 | K24: =H24*J24 -> 0
H25: =F25*G25 -> 0 | K25: =H25*J25 -> 0
H26: =F26*G26 -> 0 | K26: =H26*J26 -> 0
H27: =F27*G27 -> 0 | K27: =H27*J27 -> 0
H28: =F28*G28 -> 0 | K28: =H28*J28 -> 0
... H40: =F40*G40 -> 0 | K40: =H40*J40 -> 0
A41: 2025 | H41: =F41*G41 -> 0 | K41: =H41*J41 -> 0
H42: =F42*G42 -> 0 | K42: =H42*J42 -> 0
H43: =F43*G43 -> 0 | K43: =H43*J43 -> 0
H44: =F44*G44 -> 0 | K44: =H44*J44 -> 0
H45: =F45*G45 -> 0 | K45: =H45*J45 -> 0
H46: =F46*G46 -> 0 | K46: =H46*J46 -> 0
H47: =F47*G47 -> 0 | K47: =H47*J47 -> 0
H48: =F48*G48 -> 0 | K48: =H48*J48 -> 0
H49: =F49*G49 -> 0 | K49: =H49*J49 -> 0
H50: =F50*G50 -> 0 | K50: =H50*J50 -> 0
H51: =F51*G51 -> 0 | K51: =H51*J51 -> 0
...

Sheet Dieu Fort
B1: Data de entrada | C1: Nº do Pedido | D1: Cliente | E1: Produto | F1: Preço | G1: Quantidade | H1: Valor Total | I1: Status | J1: % Comissão | K1: Comissão total | L1: Mês a Receber
B2: 45992 | C2: 88006 | D2: EME Modas | E2: Tanga Maju | F2: 2.8 | G2: 1390 | H2: =F2*G2 -> 3892 | I2: Pago | J2: 0.02 | K2: =H2*J2 -> 77.84 | L2: Janeiro
B3: 45997 | C3: 88319 | D3: EME Modas | E3: Tanga Maju | F3: 2.8 | G3: 1055 | H3: =F3*G3 -> 2954 | I3: Pago | J3: 0.02 | K3: =H3*J3 -> 59.08 | L3: Janeiro
B4: 46008 | C4: 89156 | D4: EME Modas | E4: Tanga Maju | F4: 2.8 | G4: 1565 | H4: =F4*G4 -> 4382 | I4: Pago | J4: 0.02 | K4: =H4*J4 -> 87.64 | L4: Janeiro
B5: 46028 | C5: 90003 | D5: EME Modas | E5: Tanga Maju | F5: 2.8 | G5: 1065 | H5: =F5*G5 -> 2982 | I5: Pago | J5: 0.02 | K5: =H5*J5 -> 59.64 | L5: Fevereiro
B6: 46031 | C6: 90265 | D6: EME Modas | E6: Tanga Maju | F6: 2.8 | G6: 490 | H6: =F6*G6 -> 1372 | I6: Pago | J6: 0.02 | K6: =H6*J6 -> 27.44 | L6: Fevereiro
B7: 46035 | C7: 90731 | D7: EME Modas | E7: Tanga Maju | F7: 2.8 | G7: 1450 | H7: =F7*G7 -> 4060 | I7: Pago | J7: 0.02 | K7: =H7*J7 -> 81.2 | L7: Fevereiro
B8: 45671 | C8: 90899 | D8: EME Modas | E8: Tanga Maju | F8: 2.8 | G8: 1150 | H8: =F8*G8 -> 3220 | I8: Pago | J8: 0.02 | K8: =H8*J8 -> 64.4 | L8: Fevereiro
B9: 46048 | C9: 92161 | D9: EME Modas | E9: Tanga Maju | F9: 2.8 | G9: 2735 | H9: =F9*G9 -> 7658 | I9: Pago | J9: 0.02 | K9: =H9*J9 -> 153.16 | L9: Fevereiro
B10: 46050 | C10: 92443 | D10: EME Modas | E10: Tanga Maju | F10: 2.8 | G10: 960 | H10: =F10*G10 -> 2688 | I10: Pago | J10: 0.02 | K10: =H10*J10 -> 53.76 | L10: Fevereiro
B11: 46064 | C11: 93942 | D11: EME Modas | E11: Tanga Maju | F11: 2.8 | G11: 1900 | H11: =F11*G11 -> 5320 | I11: Pago | J11: 0.02 | K11: =H11*J11 -> 106.4 | L11: Março
B12: 46070 | C12: 94151 | D12: EME Modas | E12: Tanga Maju | F12: 2.8 | G12: 915 | H12: =F12*G12 -> 2562 | I12: Pago | J12: 0.02 | K12: =H12*J12 -> 51.24 | L12: Março
B13: 46079 | C13: 94939 | D13: EME Modas | E13: Tanga Maju | F13: 2.8 | G13: 6005 | H13: =F13*G13 -> 16814 | I13: Pago | J13: 0.02 | K13: =H13*J13 -> 336.28 | L13: Março
B14: 46080 | C14: 95034 | D14: EME Modas | E14: Tanga Maju | F14: 2.8 | G14: 1650 | H14: =F14*G14 -> 4620 | I14: Pago | J14: 0.02 | K14: =H14*J14 -> 92.4 | L14: Março
H15: =F15*G15 -> 0 | K15: =H15*J15 -> 0
H16: =F16*G16 -> 0 | K16: =H16*J16 -> 0
H17: =F17*G17 -> 0 | K17: =H17*J17 -> 0
H18: =F18*G18 -> 0 | K18: =H18*J18 -> 0
H19: =F19*G19 -> 0 | K19: =H19*J19 -> 0
H20: =F20*G20 -> 0 | K20: =H20*J20 -> 0
H21: =F21*G21 -> 0 | K21: =H21*J21 -> 0
H22: =F22*G22 -> 0 | K22: =H22*J22 -> 0
H23: =F23*G23 -> 0 | K23: =H23*J23 -> 0
H24: =F24*G24 -> 0 | K24: =H24*J24 -> 0
H25: =F25*G25 -> 0 | K25: =H25*J25 -> 0
H26: =F26*G26 -> 0 | K26: =H26*J26 -> 0
... H39: =F39*G39 -> 0 | K39: =H39*J39 -> 0
A40: 2025 | H40: =F40*G40 -> 0 | K40: =H40*J40 -> 0
H41: =F41*G41 -> 0 | K41: =H41*J41 -> 0
H42: =F42*G42 -> 0 | K42: =H42*J42 -> 0
H43: =F43*G43 -> 0 | K43: =H43*J43 -> 0
H44: =F44*G44 -> 0 | K44: =H44*J44 -> 0
H45: =F45*G45 -> 0 | K45: =H45*J45 -> 0
H46: =F46*G46 -> 0 | K46: =H46*J46 -> 0
H47: =F47*G47 -> 0 | K47: =H47*J47 -> 0
H48: =F48*G48 -> 0 | K48: =H48*J48 -> 0
H49: =F49*G49 -> 0 | K49: =H49*J49 -> 0
H50: =F50*G50 -> 0 | K50: =H50*J50 -> 0
H51: =F51*G51 -> 0 | K51: =H51*J51 -> 0
H52: =F52*G52 -> 0 | K52: =H52*J52 -> 0
...

Sheet Bônus
B1: Data de entrada | C1: Nº do Pedido | D1: Cliente | E1: Produto | F1: Preço | G1: Quantidade | H1: Valor Total | I1: Status | J1: % Comissão | K1: Comissão total | L1: Mês a Receber
B2: 46056 | D2: F7 New Style | E2: Suplex | F2: 23.9 | G2: 37.54 | H2: =F2*G2 -> 897.206 | I2: Pago | J2: 0.01 | K2: =H2*J2 -> 8.97206 | L2: Fevereiro
B3: 46057 | C3: 42177 | D3: F7 New Style | E3: Fofuxo | F3: 13.6 | G3: 60 | H3: =F3*G3 -> 816 | I3: Pago | J3: 0.0736 | K3: =H3*J3 -> 60.0576 | L3: Março
D4: Belle Fascinio Lingerie | E4: NF | F4: 3919 | G4: 100 | H4: =F4*G4 -> 391900 | I4: Pago | J4: 0.01 | K4: =H4*J4 -> 3919 | L4: Fevereiro
D5: Tornado | E5: Vendas | F5: 4.79 | G5: 10000 | H5: =F5*G5 -> 47900 | I5: Pago | J5: 0.01 | K5: =H5*J5 -> 479 | L5: Fevereiro
B6: 46153 | C6: 35452 | D6: MS Fabulosa | E6: Romantic | F6: 28.1 | G6: 56.18 | H6: =F6*G6 -> 1578.658 | I6: Pago | J6: 0.032 | K6: =H6*J6 -> 50.517056
B7: 46153 | C7: 35463 | D7: MS Fabulosa | E7: Romantic | F7: 29.9 | G7: 38.38 | H7: =F7*G7 -> 1147.562 | I7: Pago | J7: 0 | K7: =H7*J7 -> 0
B8: 46154 | C8: 35508 | D8: Time Fitness | E8: Renda 6cm | F8: 74.35 | G8: 3.6 | H8: =F8*G8 -> 267.66 | I8: Pago | J8: 0.0744 | K8: =H8*J8 -> 19.913904
B9: 46155 | C9: 35525 | D9: Fabio de simas | E9: Romantic | F9: 28 | G9: 109.36 | H9: =F9*G9 -> 3062.08 | I9: Pago | J9: 0.0294 | K9: =H9*J9 -> 90.025152
B10: 46161 | C10: 35668 | D10: MS Fabulosa | E10: Romantic | F10: 28.1 | G10: 56.98 | H10: =F10*G10 -> 1601.138 | I10: Pago | J10: 0.032 | K10: =H10*J10 -> 51.236416
B11: 46161 | C11: 35668 | D11: MS Fabulosa | E11: Romantic | F11: 28.9 | G11: 196.55 | H11: =F11*G11 -> 5680.295 | I11: Pago | J11: 0 | K11: =H11*J11 -> 0
B12: 46168 | C12: 35857 | D12: MS Fabulosa | E12: Romantic | F12: 28.1 | G12: 57.81 | H12: =F12*G12 -> 1624.461 | I12: Pago | J12: 0.032 | K12: =H12*J12 -> 51.982752
B13: 46197 | C13: 36659 | D13: Fabio de simas | E13: Romantic | F13: 28 | G13: =19.65+18.52+19.29+19.06 -> 76.52 | H13: =F13*G13 -> 2142.56 | I13: Pago | J13: 0.0294 | K13: =H13*J13 -> 62.991264
B14: 46210 | D14: MS Fabulosa | E14: Romantic | F14: 28.1 | G14: 55.78 | H14: =F14*G14 -> 1567.418 | I14: Pago | J14: 0.0272 | K14: =H14*J14 -> 42.63377
B15: 46210 | D15: MS Fabulosa | E15: Suede Canelado | F15: 26.9 | G15: 111.2 | H15: =F15*G15 -> 2991.28 | I15: Pago | K15: =H15*J15 -> 0
B16: 46212 | D16: BR acessórios | E16: Suede Canelado | F16: 26.9 | G16: 87.73 | H16: =F16*G16 -> 2359.937 | I16: Pago | K16: =H16*J16 -> 0
B17: 46224 | D17: MS Fabulosa | E17: Romantic | F17: 28.1 | G17: 57.87 | H17: =F17*G17 -> 1626.147 | I17: Pago | J17: 0.0285 | K17: =H17*J17 -> 46.345189
D18: MS Fabulosa | E18: Romantic | F18: 28.1 | G18: 58.25 | H18: =F18*G18 -> 1636.825 | I18: Pago | J18: 0.0285 | K18: =H18*J18 -> 46.649513
D19: GT Moda Intima | E19: Suede Canelado | F19: 26.9 | G19: 80 | H19: =F19*G19 -> 2152 | I19: Pago | K19: =H19*J19 -> 0
D20: MS Fabulosa | E20: Romantic | F20: 28.1 | G20: =19.74+19.58+19.08 -> 58.4 | H20: =F20*G20 -> 1641.04 | I20: Pago | J20: 0.0285 | K20: =H20*J20 -> 46.76964
H21: =F21*G21 -> 0 | K21: =H21*J21 -> 0
H22: =F22*G22 -> 0 | K22: =H22*J22 -> 0
H23: =F23*G23 -> 0 | K23: =H23*J23 -> 0
H24: =F24*G24 -> 0 | K24: =H24*J24 -> 0
H25: =F25*G25 -> 0 | K25: =H25*J25 -> 0
H26: =F26*G26 -> 0 | K26: =H26*J26 -> 0
H27: =F27*G27 -> 0 | K27: =H27*J27 -> 0
H28: =F28*G28 -> 0 | K28: =H28*J28 -> 0
H29: =F29*G29 -> 0 | K29: =H29*J29 -> 0
H30: =F30*G30 -> 0 | K30: =H30*J30 -> 0
H31: =F31*G31 -> 0 | K31: =H31*J31 -> 0
H32: =F32*G32 -> 0 | K32: =H32*J32 -> 0
... H35: =F35*G35 -> 0 | K35: =H35*J35 -> 0
A36: 2025 | H36: =F36*G36 -> 0 | K36: =H36*J36 -> 0
H37: =F37*G37 -> 0 | K37: =H37*J37 -> 0
H38: =F38*G38 -> 0 | K38: =H38*J38 -> 0
H39: =F39*G39 -> 0 | K39: =H39*J39 -> 0
H40: =F40*G40 -> 0 | K40: =H40*J40 -> 0
H41: =F41*G41 -> 0 | K41: =H41*J41 -> 0
H42: =F42*G42 -> 0 | K42: =H42*J42 -> 0
...

Sheet Total Comissão
E1: Mês a Receber | F1: Total a receber
B2: LEXUS REPRESENTAÇÕES | E2: Setembro | F2: =C7+C15 -> 5830.7305
B3: Dieu Fort | C3: =SUMIF('Dieu Fort'!L:L,E2,'Dieu Fort'!K:K) -> 0
B4: MR Têxtil | C4: =SUMIF('RM Têxtil'!L:L,E2,'RM Têxtil'!K:K) -> 69.48816 | E4: Tributavel | F4: Não Tributavel
B5: 2R Representações | C5: =SUMIF('2R Representações'!L:L,E2,'2R Representações'!K:K) -> 0 | E5: =C15 -> 5761.2423 | F5: =C7 -> 69.48816
B6: Bônus | C6: =SUMIF('Bônus'!L:L,E2,'Bônus'!K:K) -> 0
B7: Total | C7: =SUM(C3:C6) -> 69.48816
B10: Grupo Fast
B11: Fast Representações | C11: =SUMIF('Fast Representações'!N:N,E2,'Fast Representações'!M:M) -> 377.61154
B12: Fast Malhas | C12: =SUMIF('Fast Malhas'!I:I,E2,'Fast Malhas'!H:H) -> 5383.6308
B13: Fast Elásticos | C13: =SUMIF('Fast Elásticos'!K:K,E2,'Fast Elásticos'!J:J) -> 0
B14: Fast Conselheiro | C14: =SUMIF('Fast Conselheiro'!L:L,E2,'Fast Conselheiro'!K:K) -> 1806.3487
B15: Total | C15: =SUM(C10:C13) -> 5761.2423
B18: =SUM(C19:N25) -> 42082.87 | C18: Janeiro | D18: Fevereiro | E18: Março | F18: Abril | G18: Maio | H18: Junho | I18: Julho | J18: Agosto | K18: Setembro | L18: Outubro | M18: Novembro | N18: Dezembro
B19: Dieu Fort | C19: 224.56 | D19: 0 | E19: 965.34
B20: MR Têxtil | C20: 100.36 | D20: 2345.69 | E20: 363.24 | F20: 2000
B21: 2R Representações | C21: 1303.41 | D21: 838.74 | E21: 610 | F21: 496 | G21: 816
B22: Fast Representações | C22: 120.11 | D22: 603.89 | E22: 53.08
B23: Fast Malhas | C23: 8847.36 | D23: 12283.88 | E23: 7440.75
B24: Fast Elásticos | C24: 39.59 | D24: 639 | E24: 19.66
B25: Bônus | C25: 0 | D25: 479.21 | E25: 0 | F25: 1493

Sheet Despesas Lexus
C4: Mês | D4: Contabilidade | E4: S.N | F4: INSS | G4: Neg. Simples | H4: Total Mês
C5: Janeiro | D5: 500 | E5: 795.23 | F5: 476.76 | G5: 309.73 | H5: =SUM(D5:G5) -> 2081.72
C6: Fevereiro | D6: 500 | E6: 540.41 | F6: 242 | G6: 313.29 | H6: =SUM(D6:G6) -> 1595.7
C7: Março | D7: 500 | E7: 809.68 | F7: 396 | G7: 316.36 | H7: =SUM(D7:G7) -> 2022.04 | I7: ALVARÁ
C8: Abril | D8: 500 | E8: 450.82 | F8: 242 | G8: 329.41 | H8: =SUM(D8:G8)+I8 -> 2064.38 | I8: 542.15
C9: Maio | D9: 500 | E9: 206.12 | F9: 181.84 | G9: 323.41 | H9: =SUM(D9:G9) -> 1211.37
C10: Junho | D10: 500 | E10: 404.49 | F10: 231.76 | G10: 326.69 | H10: =SUM(D10:G10) -> 1462.94 | I10: CERTIFICADO
C11: Julho | D11: 500 | E11: 0 | F11: 231.76 | G11: 309.73 | H11: =D11+E11+F11+G11+I11 -> 1238.49 | I11: 197
C12: Agosto | D12: 500 | E12: 0 | F12: 0 | G12: 309.73 | H12: =SUM(D12:G12) -> 809.73
C13: Setembro | D13: 500 | E13: 0 | F13: 0 | G13: 309.73 | H13: =SUM(D13:G13) -> 809.73
C14: Outubro | D14: 500 | E14: 0 | F14: 0 | G14: 309.73 | H14: =SUM(D14:G14) -> 809.73
C15: Novembro | D15: 500 | E15: 0 | F15: 0 | G15: 309.73 | H15: =SUM(D15:G15) -> 809.73
C16: Dezembro | D16: 500 | E16: 0 | F16: 0 | G16: 309.73 | H16: =SUM(D16:G16) -> 809.73
